Workbook

Sheet Claude vs tools
A1: # | B1: Claude's concept | C1: Gemini extracted | D1: RAKE extracted | E1: YAKE extracted | F1: Group | G1: Short description (from the PDF) | H1: Tools that found it | I1: Found by | K1: Accepted tool phrase 1 | L1: Accepted tool phrase 2 | M1: Accepted tool phrase 3 | O1: Legend
A2: 1 | B2: Dynamic programming | C2: =IF(LEN(IF(K2="","",IFERROR(INDEX('Raw lists'!$A$2:$A$32,MATCH(K2,'Raw lists'!$A$2:$A$32,0))&" / ",""))&IF(L2="","",IFERROR(INDEX('Raw lists'!$A$2:$A$32,MATCH(L2,'Raw lists'!$A$2:$A$32,0))&" / ",""))&IF(M2="","",IFERROR(INDEX('Raw lists'!$A$2:$A$32,MATCH(M2,'Raw lists'!$A$2:$A$32,0))&" / ","")))=0,"",LEFT(IF(K2="","",IFERROR(INDEX('Raw lists'!$A$2:$A$32,MATCH(K2,'Raw lists'!$A$2:$A$32,0))&" / ",""))&IF(L2="","",IFERROR(INDEX('Raw lists'!$A$2:$A$32,MATCH(L2,'Raw lists'!$A$2:$A$32,0))&" / ",""))&IF(M2="","",IFERROR(INDEX('Raw lists'!$A$2:$A$32,MATCH(M2,'Raw lists'!$A$2:$A$32,0))&" / ","")),LEN(IF(K2="","",IFERROR(INDEX('Raw lists'!$A$2:$A$32,MATCH(K2,'Raw lists'!$A$2:$A$32,0))&" / ",""))&IF(L2="","",IFERROR(INDEX('Raw lists'!$A$2:$A$32,MATCH(L2,'Raw lists'!$A$2:$A$32,0))&" / ",""))&IF(M2="","",IFERROR(INDEX('Raw lists'!$A$2:$A$32,MATCH(M2,'Raw lists'!$A$2:$A$32,0))&" / ","")))-3)) | D2: =IF(LEN(IF(K2="","",IFERROR(INDEX('Raw lists'!$B$2:$B$29,MATCH(K2,'Raw lists'!$B$2:$B$29,0))&" / ",""))&IF(L2="","",IFERROR(INDEX('Raw lists'!$B$2:$B$29,MATCH(L2,'Raw lists'!$B$2:$B$29,0))&" / ",""))&IF(M2="","",IFERROR(INDEX('Raw lists'!$B$2:$B$29,MATCH(M2,'Raw lists'!$B$2:$B$29,0))&" / ","")))=0,"",LEFT(IF(K2="","",IFERROR(INDEX('Raw lists'!$B$2:$B$29,MATCH(K2,'Raw lists'!$B$2:$B$29,0))&" / ",""))&IF(L2="","",IFERROR(INDEX('Raw lists'!$B$2:$B$29,MATCH(L2,'Raw lists'!$B$2:$B$29,0))&" / ",""))&IF(M2="","",IFERROR(INDEX('Raw lists'!$B$2:$B$29,MATCH(M2,'Raw lists'!$B$2:$B$29,0))&" / ","")),LEN(IF(K2="","",IFERROR(INDEX('Raw lists'!$B$2:$B$29,MATCH(K2,'Raw lists'!$B$2:$B$29,0))&" / ",""))&IF(L2="","",IFERROR(INDEX('Raw lists'!$B$2:$B$29,MATCH(L2,'Raw lists'!$B$2:$B$29,0))&" / ",""))&IF(M2="","",IFERROR(INDEX('Raw lists'!$B$2:$B$29,MATCH(M2,'Raw lists'!$B$2:$B$29,0))&" / ","")))-3)) | E2: =IF(LEN(IF(K2="","",IFERROR(INDEX('Raw lists'!$C$2:$C$23,MATCH(K2,'Raw lists'!$C$2:$C$23,0))&" / ",""))&IF(L2="","",IFERROR(INDEX('Raw lists'!$C$2:$C$23,MATCH(L2,'Raw lists'!$C$2:$C$23,0))&" / ",""))&IF(M2="","",IFERROR(INDEX('Raw lists'!$C$2:$C$23,MATCH(M2,'Raw lists'!$C$2:$C$23,0))&" / ","")))=0,"",LEFT(IF(K2="","",IFERROR(INDEX('Raw lists'!$C$2:$C$23,MATCH(K2,'Raw lists'!$C$2:$C$23,0))&" / ",""))&IF(L2="","",IFERROR(INDEX('Raw lists'!$C$2:$C$23,MATCH(L2,'Raw lists'!$C$2:$C$23,0))&" / ",""))&IF(M2="","",IFERROR(INDEX('Raw lists'!$C$2:$C$23,MATCH(M2,'Raw lists'!$C$2:$C$23,0))&" / ","")),LEN(IF(K2="","",IFERROR(INDEX('Raw lists'!$C$2:$C$23,MATCH(K2,'Raw lists'!$C$2:$C$23,0))&" / ",""))&IF(L2="","",IFERROR(INDEX('Raw lists'!$C$2:$C$23,MATCH(L2,'Raw lists'!$C$2:$C$23,0))&" / ",""))&IF(M2="","",IFERROR(INDEX('Raw lists'!$C$2:$C$23,MATCH(M2,'Raw lists'!$C$2:$C$23,0))&" / ","")))-3)) -> Dynamic Programming / Dynamic Programming Steps | F2: Core | G2: Solve a problem through smaller subproblems, using the six SRT BOT steps. | H2: =COUNTIF(C2:E2,"?*") -> 1 | I2: =IF(H2=0,"None",IF(H2=3,"All three",IF(H2=1,"Only "&TRIM(IF(C2<>"","Gemini ","")&IF(D2<>"","RAKE ","")&IF(E2<>"","YAKE","")),SUBSTITUTE(TRIM(IF(C2<>"","Gemini ","")&IF(D2<>"","RAKE ","")&IF(E2<>"","YAKE",""))," "," + ")))) -> Only YAKE | K2: Dynamic Programming | L2: Dynamic Programming Steps | O2: Found by all three tools
A3: 2 | B3: SRT BOT | C3: =IF(LEN(IF(K3="","",IFERROR(INDEX('Raw lists'!$A$2:$A$32,MATCH(K3,'Raw lists'!$A$2:$A$32,0))&" / ",""))&IF(L3="","",IFERROR(INDEX('Raw lists'!$A$2:$A$32,MATCH(L3,'Raw lists'!$A$2:$A$32,0))&" / ",""))&IF(M3="","",IFERROR(INDEX('Raw lists'!$A$2:$A$32,MATCH(M3,'Raw lists'!$A$2:$A$32,0))&" / ","")))=0,"",LEFT(IF(K3="","",IFERROR(INDEX('Raw lists'!$A$2:$A$32,MATCH(K3,'Raw lists'!$A$2:$A$32,0))&" / ",""))&IF(L3="","",IFERROR(INDEX('Raw lists'!$A$2:$A$32,MATCH(L3,'Raw lists'!$A$2:$A$32,0))&" / ",""))&IF(M3="","",IFERROR(INDEX('Raw lists'!$A$2:$A$32,MATCH(M3,'Raw lists'!$A$2:$A$32,0))&" / ","")),LEN(IF(K3="","",IFERROR(INDEX('Raw lists'!$A$2:$A$32,MATCH(K3,'Raw lists'!$A$2:$A$32,0))&" / ",""))&IF(L3="","",IFERROR(INDEX('Raw lists'!$A$2:$A$32,MATCH(L3,'Raw lists'!$A$2:$A$32,0))&" / ",""))&IF(M3="","",IFERROR(INDEX('Raw lists'!$A$2:$A$32,MATCH(M3,'Raw lists'!$A$2:$A$32,0))&" / ","")))-3)) | D3: =IF(LEN(IF(K3="","",IFERROR(INDEX('Raw lists'!$B$2:$B$29,MATCH(K3,'Raw lists'!$B$2:$B$29,0))&" / ",""))&IF(L3="","",IFERROR(INDEX('Raw lists'!$B$2:$B$29,MATCH(L3,'Raw lists'!$B$2:$B$29,0))&" / ",""))&IF(M3="","",IFERROR(INDEX('Raw lists'!$B$2:$B$29,MATCH(M3,'Raw lists'!$B$2:$B$29,0))&" / ","")))=0,"",LEFT(IF(K3="","",IFERROR(INDEX('Raw lists'!$B$2:$B$29,MATCH(K3,'Raw lists'!$B$2:$B$29,0))&" / ",""))&IF(L3="","",IFERROR(INDEX('Raw lists'!$B$2:$B$29,MATCH(L3,'Raw lists'!$B$2:$B$29,0))&" / ",""))&IF(M3="","",IFERROR(INDEX('Raw lists'!$B$2:$B$29,MATCH(M3,'Raw lists'!$B$2:$B$29,0))&" / ","")),LEN(IF(K3="","",IFERROR(INDEX('Raw lists'!$B$2:$B$29,MATCH(K3,'Raw lists'!$B$2:$B$29,0))&" / ",""))&IF(L3="","",IFERROR(INDEX('Raw lists'!$B$2:$B$29,MATCH(L3,'Raw lists'!$B$2:$B$29,0))&" / ",""))&IF(M3="","",IFERROR(INDEX('Raw lists'!$B$2:$B$29,MATCH(M3,'Raw lists'!$B$2:$B$29,0))&" / ","")))-3)) | E3: =IF(LEN(IF(K3="","",IFERROR(INDEX('Raw lists'!$C$2:$C$23,MATCH(K3,'Raw lists'!$C$2:$C$23,0))&" / ",""))&IF(L3="","",IFERROR(INDEX('Raw lists'!$C$2:$C$23,MATCH(L3,'Raw lists'!$C$2:$C$23,0))&" / ",""))&IF(M3="","",IFERROR(INDEX('Raw lists'!$C$2:$C$23,MATCH(M3,'Raw lists'!$C$2:$C$23,0))&" / ","")))=0,"",LEFT(IF(K3="","",IFERROR(INDEX('Raw lists'!$C$2:$C$23,MATCH(K3,'Raw lists'!$C$2:$C$23,0))&" / ",""))&IF(L3="","",IFERROR(INDEX('Raw lists'!$C$2:$C$23,MATCH(L3,'Raw lists'!$C$2:$C$23,0))&" / ",""))&IF(M3="","",IFERROR(INDEX('Raw lists'!$C$2:$C$23,MATCH(M3,'Raw lists'!$C$2:$C$23,0))&" / ","")),LEN(IF(K3="","",IFERROR(INDEX('Raw lists'!$C$2:$C$23,MATCH(K3,'Raw lists'!$C$2:$C$23,0))&" / ",""))&IF(L3="","",IFERROR(INDEX('Raw lists'!$C$2:$C$23,MATCH(L3,'Raw lists'!$C$2:$C$23,0))&" / ",""))&IF(M3="","",IFERROR(INDEX('Raw lists'!$C$2:$C$23,MATCH(M3,'Raw lists'!$C$2:$C$23,0))&" / ","")))-3)) -> Srt Bot | F3: Core | G3: The lecture's six-step recipe: Subproblem, Relate, Topological order, Base cases, Original problem, Time. | H3: =COUNTIF(C3:E3,"?*") -> 1 | I3: =IF(H3=0,"None",IF(H3=3,"All three",IF(H3=1,"Only "&TRIM(IF(C3<>"","Gemini ","")&IF(D3<>"","RAKE ","")&IF(E3<>"","YAKE","")),SUBSTITUTE(TRIM(IF(C3<>"","Gemini ","")&IF(D3<>"","RAKE ","")&IF(E3<>"","YAKE",""))," "," + ")))) -> Only YAKE | K3: Srt Bot | O3: Found by two tools
A4: 3 | B4: Subproblem definition | C4: =IF(LEN(IF(K4="","",IFERROR(INDEX('Raw lists'!$A$2:$A$32,MATCH(K4,'Raw lists'!$A$2:$A$32,0))&" / ",""))&IF(L4="","",IFERROR(INDEX('Raw lists'!$A$2:$A$32,MATCH(L4,'Raw lists'!$A$2:$A$32,0))&" / ",""))&IF(M4="","",IFERROR(INDEX('Raw lists'!$A$2:$A$32,MATCH(M4,'Raw lists'!$A$2:$A$32,0))&" / ","")))=0,"",LEFT(IF(K4="","",IFERROR(INDEX('Raw lists'!$A$2:$A$32,MATCH(K4,'Raw lists'!$A$2:$A$32,0))&" / ",""))&IF(L4="","",IFERROR(INDEX('Raw lists'!$A$2:$A$32,MATCH(L4,'Raw lists'!$A$2:$A$32,0))&" / ",""))&IF(M4="","",IFERROR(INDEX('Raw lists'!$A$2:$A$32,MATCH(M4,'Raw lists'!$A$2:$A$32,0))&" / ","")),LEN(IF(K4="","",IFERROR(INDEX('Raw lists'!$A$2:$A$32,MATCH(K4,'Raw lists'!$A$2:$A$32,0))&" / ",""))&IF(L4="","",IFERROR(INDEX('Raw lists'!$A$2:$A$32,MATCH(L4,'Raw lists'!$A$2:$A$32,0))&" / ",""))&IF(M4="","",IFERROR(INDEX('Raw lists'!$A$2:$A$32,MATCH(M4,'Raw lists'!$A$2:$A$32,0))&" / ","")))-3)) | D4: =IF(LEN(IF(K4="","",IFERROR(INDEX('Raw lists'!$B$2:$B$29,MATCH(K4,'Raw lists'!$B$2:$B$29,0))&" / ",""))&IF(L4="","",IFERROR(INDEX('Raw lists'!$B$2:$B$29,MATCH(L4,'Raw lists'!$B$2:$B$29,0))&" / ",""))&IF(M4="","",IFERROR(INDEX('Raw lists'!$B$2:$B$29,MATCH(M4,'Raw lists'!$B$2:$B$29,0))&" / ","")))=0,"",LEFT(IF(K4="","",IFERROR(INDEX('Raw lists'!$B$2:$B$29,MATCH(K4,'Raw lists'!$B$2:$B$29,0))&" / ",""))&IF(L4="","",IFERROR(INDEX('Raw lists'!$B$2:$B$29,MATCH(L4,'Raw lists'!$B$2:$B$29,0))&" / ",""))&IF(M4="","",IFERROR(INDEX('Raw lists'!$B$2:$B$29,MATCH(M4,'Raw lists'!$B$2:$B$29,0))&" / ","")),LEN(IF(K4="","",IFERROR(INDEX('Raw lists'!$B$2:$B$29,MATCH(K4,'Raw lists'!$B$2:$B$29,0))&" / ",""))&IF(L4="","",IFERROR(INDEX('Raw lists'!$B$2:$B$29,MATCH(L4,'Raw lists'!$B$2:$B$29,0))&" / ",""))&IF(M4="","",IFERROR(INDEX('Raw lists'!$B$2:$B$29,MATCH(M4,'Raw lists'!$B$2:$B$29,0))&" / ","")))-3)) -> Subproblem / Subproblems | E4: =IF(LEN(IF(K4="","",IFERROR(INDEX('Raw lists'!$C$2:$C$23,MATCH(K4,'Raw lists'!$C$2:$C$23,0))&" / ",""))&IF(L4="","",IFERROR(INDEX('Raw lists'!$C$2:$C$23,MATCH(L4,'Raw lists'!$C$2:$C$23,0))&" / ",""))&IF(M4="","",IFERROR(INDEX('Raw lists'!$C$2:$C$23,MATCH(M4,'Raw lists'!$C$2:$C$23,0))&" / ","")))=0,"",LEFT(IF(K4="","",IFERROR(INDEX('Raw lists'!$C$2:$C$23,MATCH(K4,'Raw lists'!$C$2:$C$23,0))&" / ",""))&IF(L4="","",IFERROR(INDEX('Raw lists'!$C$2:$C$23,MATCH(L4,'Raw lists'!$C$2:$C$23,0))&" / ",""))&IF(M4="","",IFERROR(INDEX('Raw lists'!$C$2:$C$23,MATCH(M4,'Raw lists'!$C$2:$C$23,0))&" / ","")),LEN(IF(K4="","",IFERROR(INDEX('Raw lists'!$C$2:$C$23,MATCH(K4,'Raw lists'!$C$2:$C$23,0))&" / ",""))&IF(L4="","",IFERROR(INDEX('Raw lists'!$C$2:$C$23,MATCH(L4,'Raw lists'!$C$2:$C$23,0))&" / ",""))&IF(M4="","",IFERROR(INDEX('Raw lists'!$C$2:$C$23,MATCH(M4,'Raw lists'!$C$2:$C$23,0))&" / ","")))-3)) -> Subproblem / Subproblems | F4: Core | G4: Describe in words what a subproblem means, in terms of its parameters. | H4: =COUNTIF(C4:E4,"?*") -> 2 | I4: =IF(H4=0,"None",IF(H4=3,"All three",IF(H4=1,"Only "&TRIM(IF(C4<>"","Gemini ","")&IF(D4<>"","RAKE ","")&IF(E4<>"","YAKE","")),SUBSTITUTE(TRIM(IF(C4<>"","Gemini ","")&IF(D4<>"","RAKE ","")&IF(E4<>"","YAKE",""))," "," + ")))) -> RAKE + YAKE | K4: Subproblem | L4: Subproblems | O4: Found by none of the tools
A5: 4 | B5: Relate (recurrence relation) | C5: =IF(LEN(IF(K5="","",IFERROR(INDEX('Raw lists'!$A$2:$A$32,MATCH(K5,'Raw lists'!$A$2:$A$32,0))&" / ",""))&IF(L5="","",IFERROR(INDEX('Raw lists'!$A$2:$A$32,MATCH(L5,'Raw lists'!$A$2:$A$32,0))&" / ",""))&IF(M5="","",IFERROR(INDEX('Raw lists'!$A$2:$A$32,MATCH(M5,'Raw lists'!$A$2:$A$32,0))&" / ","")))=0,"",LEFT(IF(K5="","",IFERROR(INDEX('Raw lists'!$A$2:$A$32,MATCH(K5,'Raw lists'!$A$2:$A$32,0))&" / ",""))&IF(L5="","",IFERROR(INDEX('Raw lists'!$A$2:$A$32,MATCH(L5,'Raw lists'!$A$2:$A$32,0))&" / ",""))&IF(M5="","",IFERROR(INDEX('Raw lists'!$A$2:$A$32,MATCH(M5,'Raw lists'!$A$2:$A$32,0))&" / ","")),LEN(IF(K5="","",IFERROR(INDEX('Raw lists'!$A$2:$A$32,MATCH(K5,'Raw lists'!$A$2:$A$32,0))&" / ",""))&IF(L5="","",IFERROR(INDEX('Raw lists'!$A$2:$A$32,MATCH(L5,'Raw lists'!$A$2:$A$32,0))&" / ",""))&IF(M5="","",IFERROR(INDEX('Raw lists'!$A$2:$A$32,MATCH(M5,'Raw lists'!$A$2:$A$32,0))&" / ","")))-3)) | D5: =IF(LEN(IF(K5="","",IFERROR(INDEX('Raw lists'!$B$2:$B$29,MATCH(K5,'Raw lists'!$B$2:$B$29,0))&" / ",""))&IF(L5="","",IFERROR(INDEX('Raw lists'!$B$2:$B$29,MATCH(L5,'Raw lists'!$B$2:$B$29,0))&" / ",""))&IF(M5="","",IFERROR(INDEX('Raw lists'!$B$2:$B$29,MATCH(M5,'Raw lists'!$B$2:$B$29,0))&" / ","")))=0,"",LEFT(IF(K5="","",IFERROR(INDEX('Raw lists'!$B$2:$B$29,MATCH(K5,'Raw lists'!$B$2:$B$29,0))&" / ",""))&IF(L5="","",IFERROR(INDEX('Raw lists'!$B$2:$B$29,MATCH(L5,'Raw lists'!$B$2:$B$29,0))&" / ",""))&IF(M5="","",IFERROR(INDEX('Raw lists'!$B$2:$B$29,MATCH(M5,'Raw lists'!$B$2:$B$29,0))&" / ","")),LEN(IF(K5="","",IFERROR(INDEX('Raw lists'!$B$2:$B$29,MATCH(K5,'Raw lists'!$B$2:$B$29,0))&" / ",""))&IF(L5="","",IFERROR(INDEX('Raw lists'!$B$2:$B$29,MATCH(L5,'Raw lists'!$B$2:$B$29,0))&" / ",""))&IF(M5="","",IFERROR(INDEX('Raw lists'!$B$2:$B$29,MATCH(M5,'Raw lists'!$B$2:$B$29,0))&" / ","")))-3)) -> Relate / Relation | E5: =IF(LEN(IF(K5="","",IFERROR(INDEX('Raw lists'!$C$2:$C$23,MATCH(K5,'Raw lists'!$C$2:$C$23,0))&" / ",""))&IF(L5="","",IFERROR(INDEX('Raw lists'!$C$2:$C$23,MATCH(L5,'Raw lists'!$C$2:$C$23,0))&" / ",""))&IF(M5="","",IFERROR(INDEX('Raw lists'!$C$2:$C$23,MATCH(M5,'Raw lists'!$C$2:$C$23,0))&" / ","")))=0,"",LEFT(IF(K5="","",IFERROR(INDEX('Raw lists'!$C$2:$C$23,MATCH(K5,'Raw lists'!$C$2:$C$23,0))&" / ",""))&IF(L5="","",IFERROR(INDEX('Raw lists'!$C$2:$C$23,MATCH(L5,'Raw lists'!$C$2:$C$23,0))&" / ",""))&IF(M5="","",IFERROR(INDEX('Raw lists'!$C$2:$C$23,MATCH(M5,'Raw lists'!$C$2:$C$23,0))&" / ","")),LEN(IF(K5="","",IFERROR(INDEX('Raw lists'!$C$2:$C$23,MATCH(K5,'Raw lists'!$C$2:$C$23,0))&" / ",""))&IF(L5="","",IFERROR(INDEX('Raw lists'!$C$2:$C$23,MATCH(L5,'Raw lists'!$C$2:$C$23,0))&" / ",""))&IF(M5="","",IFERROR(INDEX('Raw lists'!$C$2:$C$23,MATCH(M5,'Raw lists'!$C$2:$C$23,0))&" / ","")))-3)) | F5: Core | G5: Express a subproblem's solution using solutions of smaller subproblems. | H5: =COUNTIF(C5:E5,"?*") -> 1 | I5: =IF(H5=0,"None",IF(H5=3,"All three",IF(H5=1,"Only "&TRIM(IF(C5<>"","Gemini ","")&IF(D5<>"","RAKE ","")&IF(E5<>"","YAKE","")),SUBSTITUTE(TRIM(IF(C5<>"","Gemini ","")&IF(D5<>"","RAKE ","")&IF(E5<>"","YAKE",""))," "," + ")))) -> Only RAKE | K5: Relate | L5: Relation | O5: Extracted by tools, not in Claude's list
A6: 5 | B6: Guessing (locally brute-force) | C6: =IF(LEN(IF(K6="","",IFERROR(INDEX('Raw lists'!$A$2:$A$32,MATCH(K6,'Raw lists'!$A$2:$A$32,0))&" / ",""))&IF(L6="","",IFERROR(INDEX('Raw lists'!$A$2:$A$32,MATCH(L6,'Raw lists'!$A$2:$A$32,0))&" / ",""))&IF(M6="","",IFERROR(INDEX('Raw lists'!$A$2:$A$32,MATCH(M6,'Raw lists'!$A$2:$A$32,0))&" / ","")))=0,"",LEFT(IF(K6="","",IFERROR(INDEX('Raw lists'!$A$2:$A$32,MATCH(K6,'Raw lists'!$A$2:$A$32,0))&" / ",""))&IF(L6="","",IFERROR(INDEX('Raw lists'!$A$2:$A$32,MATCH(L6,'Raw lists'!$A$2:$A$32,0))&" / ",""))&IF(M6="","",IFERROR(INDEX('Raw lists'!$A$2:$A$32,MATCH(M6,'Raw lists'!$A$2:$A$32,0))&" / ","")),LEN(IF(K6="","",IFERROR(INDEX('Raw lists'!$A$2:$A$32,MATCH(K6,'Raw lists'!$A$2:$A$32,0))&" / ",""))&IF(L6="","",IFERROR(INDEX('Raw lists'!$A$2:$A$32,MATCH(L6,'Raw lists'!$A$2:$A$32,0))&" / ",""))&IF(M6="","",IFERROR(INDEX('Raw lists'!$A$2:$A$32,MATCH(M6,'Raw lists'!$A$2:$A$32,0))&" / ","")))-3)) | D6: =IF(LEN(IF(K6="","",IFERROR(INDEX('Raw lists'!$B$2:$B$29,MATCH(K6,'Raw lists'!$B$2:$B$29,0))&" / ",""))&IF(L6="","",IFERROR(INDEX('Raw lists'!$B$2:$B$29,MATCH(L6,'Raw lists'!$B$2:$B$29,0))&" / ",""))&IF(M6="","",IFERROR(INDEX('Raw lists'!$B$2:$B$29,MATCH(M6,'Raw lists'!$B$2:$B$29,0))&" / ","")))=0,"",LEFT(IF(K6="","",IFERROR(INDEX('Raw lists'!$B$2:$B$29,MATCH(K6,'Raw lists'!$B$2:$B$29,0))&" / ",""))&IF(L6="","",IFERROR(INDEX('Raw lists'!$B$2:$B$29,MATCH(L6,'Raw lists'!$B$2:$B$29,0))&" / ",""))&IF(M6="","",IFERROR(INDEX('Raw lists'!$B$2:$B$29,MATCH(M6,'Raw lists'!$B$2:$B$29,0))&" / ","")),LEN(IF(K6="","",IFERROR(INDEX('Raw lists'!$B$2:$B$29,MATCH(K6,'Raw lists'!$B$2:$B$29,0))&" / ",""))&IF(L6="","",IFERROR(INDEX('Raw lists'!$B$2:$B$29,MATCH(L6,'Raw lists'!$B$2:$B$29,0))&" / ",""))&IF(M6="","",IFERROR(INDEX('Raw lists'!$B$2:$B$29,MATCH(M6,'Raw lists'!$B$2:$B$29,0))&" / ","")))-3)) | E6: =IF(LEN(IF(K6="","",IFERROR(INDEX('Raw lists'!$C$2:$C$23,MATCH(K6,'Raw lists'!$C$2:$C$23,0))&" / ",""))&IF(L6="","",IFERROR(INDEX('Raw lists'!$C$2:$C$23,MATCH(L6,'Raw lists'!$C$2:$C$23,0))&" / ",""))&IF(M6="","",IFERROR(INDEX('Raw lists'!$C$2:$C$23,MATCH(M6,'Raw lists'!$C$2:$C$23,0))&" / ","")))=0,"",LEFT(IF(K6="","",IFERROR(INDEX('Raw lists'!$C$2:$C$23,MATCH(K6,'Raw lists'!$C$2:$C$23,0))&" / ",""))&IF(L6="","",IFERROR(INDEX('Raw lists'!$C$2:$C$23,MATCH(L6,'Raw lists'!$C$2:$C$23,0))&" / ",""))&IF(M6="","",IFERROR(INDEX('Raw lists'!$C$2:$C$23,MATCH(M6,'Raw lists'!$C$2:$C$23,0))&" / ","")),LEN(IF(K6="","",IFERROR(INDEX('Raw lists'!$C$2:$C$23,MATCH(K6,'Raw lists'!$C$2:$C$23,0))&" / ",""))&IF(L6="","",IFERROR(INDEX('Raw lists'!$C$2:$C$23,MATCH(L6,'Raw lists'!$C$2:$C$23,0))&" / ",""))&IF(M6="","",IFERROR(INDEX('Raw lists'!$C$2:$C$23,MATCH(M6,'Raw lists'!$C$2:$C$23,0))&" / ","")))-3)) | F6: Core | G6: Try all possible answers to a question that would reduce the subproblem. | H6: =COUNTIF(C6:E6,"?*") -> 0 | I6: =IF(H6=0,"None",IF(H6=3,"All three",IF(H6=1,"Only "&TRIM(IF(C6<>"","Gemini ","")&IF(D6<>"","RAKE ","")&IF(E6<>"","YAKE","")),SUBSTITUTE(TRIM(IF(C6<>"","Gemini ","")&IF(D6<>"","RAKE ","")&IF(E6<>"","YAKE",""))," "," + ")))) -> None | K6: Guess | L6: Guessing | O6: Dark green cells show the phrase each tool extracted for that concept.
A7: 6 | B7: Topological order | C7: =IF(LEN(IF(K7="","",IFERROR(INDEX('Raw lists'!$A$2:$A$32,MATCH(K7,'Raw lists'!$A$2:$A$32,0))&" / ",""))&IF(L7="","",IFERROR(INDEX('Raw lists'!$A$2:$A$32,MATCH(L7,'Raw lists'!$A$2:$A$32,0))&" / ",""))&IF(M7="","",IFERROR(INDEX('Raw lists'!$A$2:$A$32,MATCH(M7,'Raw lists'!$A$2:$A$32,0))&" / ","")))=0,"",LEFT(IF(K7="","",IFERROR(INDEX('Raw lists'!$A$2:$A$32,MATCH(K7,'Raw lists'!$A$2:$A$32,0))&" / ",""))&IF(L7="","",IFERROR(INDEX('Raw lists'!$A$2:$A$32,MATCH(L7,'Raw lists'!$A$2:$A$32,0))&" / ",""))&IF(M7="","",IFERROR(INDEX('Raw lists'!$A$2:$A$32,MATCH(M7,'Raw lists'!$A$2:$A$32,0))&" / ","")),LEN(IF(K7="","",IFERROR(INDEX('Raw lists'!$A$2:$A$32,MATCH(K7,'Raw lists'!$A$2:$A$32,0))&" / ",""))&IF(L7="","",IFERROR(INDEX('Raw lists'!$A$2:$A$32,MATCH(L7,'Raw lists'!$A$2:$A$32,0))&" / ",""))&IF(M7="","",IFERROR(INDEX('Raw lists'!$A$2:$A$32,MATCH(M7,'Raw lists'!$A$2:$A$32,0))&" / ","")))-3)) | D7: =IF(LEN(IF(K7="","",IFERROR(INDEX('Raw lists'!$B$2:$B$29,MATCH(K7,'Raw lists'!$B$2:$B$29,0))&" / ",""))&IF(L7="","",IFERROR(INDEX('Raw lists'!$B$2:$B$29,MATCH(L7,'Raw lists'!$B$2:$B$29,0))&" / ",""))&IF(M7="","",IFERROR(INDEX('Raw lists'!$B$2:$B$29,MATCH(M7,'Raw lists'!$B$2:$B$29,0))&" / ","")))=0,"",LEFT(IF(K7="","",IFERROR(INDEX('Raw lists'!$B$2:$B$29,MATCH(K7,'Raw lists'!$B$2:$B$29,0))&" / ",""))&IF(L7="","",IFERROR(INDEX('Raw lists'!$B$2:$B$29,MATCH(L7,'Raw lists'!$B$2:$B$29,0))&" / ",""))&IF(M7="","",IFERROR(INDEX('Raw lists'!$B$2:$B$29,MATCH(M7,'Raw lists'!$B$2:$B$29,0))&" / ","")),LEN(IF(K7="","",IFERROR(INDEX('Raw lists'!$B$2:$B$29,MATCH(K7,'Raw lists'!$B$2:$B$29,0))&" / ",""))&IF(L7="","",IFERROR(INDEX('Raw lists'!$B$2:$B$29,MATCH(L7,'Raw lists'!$B$2:$B$29,0))&" / ",""))&IF(M7="","",IFERROR(INDEX('Raw lists'!$B$2:$B$29,MATCH(M7,'Raw lists'!$B$2:$B$29,0))&" / ","")))-3)) | E7: =IF(LEN(IF(K7="","",IFERROR(INDEX('Raw lists'!$C$2:$C$23,MATCH(K7,'Raw lists'!$C$2:$C$23,0))&" / ",""))&IF(L7="","",IFERROR(INDEX('Raw lists'!$C$2:$C$23,MATCH(L7,'Raw lists'!$C$2:$C$23,0))&" / ",""))&IF(M7="","",IFERROR(INDEX('Raw lists'!$C$2:$C$23,MATCH(M7,'Raw lists'!$C$2:$C$23,0))&" / ","")))=0,"",LEFT(IF(K7="","",IFERROR(INDEX('Raw lists'!$C$2:$C$23,MATCH(K7,'Raw lists'!$C$2:$C$23,0))&" / ",""))&IF(L7="","",IFERROR(INDEX('Raw lists'!$C$2:$C$23,MATCH(L7,'Raw lists'!$C$2:$C$23,0))&" / ",""))&IF(M7="","",IFERROR(INDEX('Raw lists'!$C$2:$C$23,MATCH(M7,'Raw lists'!$C$2:$C$23,0))&" / ","")),LEN(IF(K7="","",IFERROR(INDEX('Raw lists'!$C$2:$C$23,MATCH(K7,'Raw lists'!$C$2:$C$23,0))&" / ",""))&IF(L7="","",IFERROR(INDEX('Raw lists'!$C$2:$C$23,MATCH(L7,'Raw lists'!$C$2:$C$23,0))&" / ",""))&IF(M7="","",IFERROR(INDEX('Raw lists'!$C$2:$C$23,MATCH(M7,'Raw lists'!$C$2:$C$23,0))&" / ","")))-3)) | F7: Core | G7: An order of the subproblems that shows the relation is acyclic. | H7: =COUNTIF(C7:E7,"?*") -> 0 | I7: =IF(H7=0,"None",IF(H7=3,"All three",IF(H7=1,"Only "&TRIM(IF(C7<>"","Gemini ","")&IF(D7<>"","RAKE ","")&IF(E7<>"","YAKE","")),SUBSTITUTE(TRIM(IF(C7<>"","Gemini ","")&IF(D7<>"","RAKE ","")&IF(E7<>"","YAKE",""))," "," + ")))) -> None | K7: Topological Order
A8: 7 | B8: Subproblem DAG (dependency graph) | C8: =IF(LEN(IF(K8="","",IFERROR(INDEX('Raw lists'!$A$2:$A$32,MATCH(K8,'Raw lists'!$A$2:$A$32,0))&" / ",""))&IF(L8="","",IFERROR(INDEX('Raw lists'!$A$2:$A$32,MATCH(L8,'Raw lists'!$A$2:$A$32,0))&" / ",""))&IF(M8="","",IFERROR(INDEX('Raw lists'!$A$2:$A$32,MATCH(M8,'Raw lists'!$A$2:$A$32,0))&" / ","")))=0,"",LEFT(IF(K8="","",IFERROR(INDEX('Raw lists'!$A$2:$A$32,MATCH(K8,'Raw lists'!$A$2:$A$32,0))&" / ",""))&IF(L8="","",IFERROR(INDEX('Raw lists'!$A$2:$A$32,MATCH(L8,'Raw lists'!$A$2:$A$32,0))&" / ",""))&IF(M8="","",IFERROR(INDEX('Raw lists'!$A$2:$A$32,MATCH(M8,'Raw lists'!$A$2:$A$32,0))&" / ","")),LEN(IF(K8="","",IFERROR(INDEX('Raw lists'!$A$2:$A$32,MATCH(K8,'Raw lists'!$A$2:$A$32,0))&" / ",""))&IF(L8="","",IFERROR(INDEX('Raw lists'!$A$2:$A$32,MATCH(L8,'Raw lists'!$A$2:$A$32,0))&" / ",""))&IF(M8="","",IFERROR(INDEX('Raw lists'!$A$2:$A$32,MATCH(M8,'Raw lists'!$A$2:$A$32,0))&" / ","")))-3)) | D8: =IF(LEN(IF(K8="","",IFERROR(INDEX('Raw lists'!$B$2:$B$29,MATCH(K8,'Raw lists'!$B$2:$B$29,0))&" / ",""))&IF(L8="","",IFERROR(INDEX('Raw lists'!$B$2:$B$29,MATCH(L8,'Raw lists'!$B$2:$B$29,0))&" / ",""))&IF(M8="","",IFERROR(INDEX('Raw lists'!$B$2:$B$29,MATCH(M8,'Raw lists'!$B$2:$B$29,0))&" / ","")))=0,"",LEFT(IF(K8="","",IFERROR(INDEX('Raw lists'!$B$2:$B$29,MATCH(K8,'Raw lists'!$B$2:$B$29,0))&" / ",""))&IF(L8="","",IFERROR(INDEX('Raw lists'!$B$2:$B$29,MATCH(L8,'Raw lists'!$B$2:$B$29,0))&" / ",""))&IF(M8="","",IFERROR(INDEX('Raw lists'!$B$2:$B$29,MATCH(M8,'Raw lists'!$B$2:$B$29,0))&" / ","")),LEN(IF(K8="","",IFERROR(INDEX('Raw lists'!$B$2:$B$29,MATCH(K8,'Raw lists'!$B$2:$B$29,0))&" / ",""))&IF(L8="","",IFERROR(INDEX('Raw lists'!$B$2:$B$29,MATCH(L8,'Raw lists'!$B$2:$B$29,0))&" / ",""))&IF(M8="","",IFERROR(INDEX('Raw lists'!$B$2:$B$29,MATCH(M8,'Raw lists'!$B$2:$B$29,0))&" / ","")))-3)) | E8: =IF(LEN(IF(K8="","",IFERROR(INDEX('Raw lists'!$C$2:$C$23,MATCH(K8,'Raw lists'!$C$2:$C$23,0))&" / ",""))&IF(L8="","",IFERROR(INDEX('Raw lists'!$C$2:$C$23,MATCH(L8,'Raw lists'!$C$2:$C$23,0))&" / ",""))&IF(M8="","",IFERROR(INDEX('Raw lists'!$C$2:$C$23,MATCH(M8,'Raw lists'!$C$2:$C$23,0))&" / ","")))=0,"",LEFT(IF(K8="","",IFERROR(INDEX('Raw lists'!$C$2:$C$23,MATCH(K8,'Raw lists'!$C$2:$C$23,0))&" / ",""))&IF(L8="","",IFERROR(INDEX('Raw lists'!$C$2:$C$23,MATCH(L8,'Raw lists'!$C$2:$C$23,0))&" / ",""))&IF(M8="","",IFERROR(INDEX('Raw lists'!$C$2:$C$23,MATCH(M8,'Raw lists'!$C$2:$C$23,0))&" / ","")),LEN(IF(K8="","",IFERROR(INDEX('Raw lists'!$C$2:$C$23,MATCH(K8,'Raw lists'!$C$2:$C$23,0))&" / ",""))&IF(L8="","",IFERROR(INDEX('Raw lists'!$C$2:$C$23,MATCH(L8,'Raw lists'!$C$2:$C$23,0))&" / ",""))&IF(M8="","",IFERROR(INDEX('Raw lists'!$C$2:$C$23,MATCH(M8,'Raw lists'!$C$2:$C$23,0))&" / ","")))-3)) | F8: Core | G8: Subproblems as nodes and dependencies as edges; it must have no cycles. | H8: =COUNTIF(C8:E8,"?*") -> 0 | I8: =IF(H8=0,"None",IF(H8=3,"All three",IF(H8=1,"Only "&TRIM(IF(C8<>"","Gemini ","")&IF(D8<>"","RAKE ","")&IF(E8<>"","YAKE","")),SUBSTITUTE(TRIM(IF(C8<>"","Gemini ","")&IF(D8<>"","RAKE ","")&IF(E8<>"","YAKE",""))," "," + ")))) -> None | K8: Dependency Graph | L8: Subproblem DAG | O8: Rows 2 to 48 are Claude's concepts. The grey rows below them list every other item from the three text files. Columns K to M (grey headers) hold the tool phrases that count as a match; edit them and the green cells update.
A9: 8 | B9: Base cases | C9: =IF(LEN(IF(K9="","",IFERROR(INDEX('Raw lists'!$A$2:$A$32,MATCH(K9,'Raw lists'!$A$2:$A$32,0))&" / ",""))&IF(L9="","",IFERROR(INDEX('Raw lists'!$A$2:$A$32,MATCH(L9,'Raw lists'!$A$2:$A$32,0))&" / ",""))&IF(M9="","",IFERROR(INDEX('Raw lists'!$A$2:$A$32,MATCH(M9,'Raw lists'!$A$2:$A$32,0))&" / ","")))=0,"",LEFT(IF(K9="","",IFERROR(INDEX('Raw lists'!$A$2:$A$32,MATCH(K9,'Raw lists'!$A$2:$A$32,0))&" / ",""))&IF(L9="","",IFERROR(INDEX('Raw lists'!$A$2:$A$32,MATCH(L9,'Raw lists'!$A$2:$A$32,0))&" / ",""))&IF(M9="","",IFERROR(INDEX('Raw lists'!$A$2:$A$32,MATCH(M9,'Raw lists'!$A$2:$A$32,0))&" / ","")),LEN(IF(K9="","",IFERROR(INDEX('Raw lists'!$A$2:$A$32,MATCH(K9,'Raw lists'!$A$2:$A$32,0))&" / ",""))&IF(L9="","",IFERROR(INDEX('Raw lists'!$A$2:$A$32,MATCH(L9,'Raw lists'!$A$2:$A$32,0))&" / ",""))&IF(M9="","",IFERROR(INDEX('Raw lists'!$A$2:$A$32,MATCH(M9,'Raw lists'!$A$2:$A$32,0))&" / ","")))-3)) -> Base Case | D9: =IF(LEN(IF(K9="","",IFERROR(INDEX('Raw lists'!$B$2:$B$29,MATCH(K9,'Raw lists'!$B$2:$B$29,0))&" / ",""))&IF(L9="","",IFERROR(INDEX('Raw lists'!$B$2:$B$29,MATCH(L9,'Raw lists'!$B$2:$B$29,0))&" / ",""))&IF(M9="","",IFERROR(INDEX('Raw lists'!$B$2:$B$29,MATCH(M9,'Raw lists'!$B$2:$B$29,0))&" / ","")))=0,"",LEFT(IF(K9="","",IFERROR(INDEX('Raw lists'!$B$2:$B$29,MATCH(K9,'Raw lists'!$B$2:$B$29,0))&" / ",""))&IF(L9="","",IFERROR(INDEX('Raw lists'!$B$2:$B$29,MATCH(L9,'Raw lists'!$B$2:$B$29,0))&" / ",""))&IF(M9="","",IFERROR(INDEX('Raw lists'!$B$2:$B$29,MATCH(M9,'Raw lists'!$B$2:$B$29,0))&" / ","")),LEN(IF(K9="","",IFERROR(INDEX('Raw lists'!$B$2:$B$29,MATCH(K9,'Raw lists'!$B$2:$B$29,0))&" / ",""))&IF(L9="","",IFERROR(INDEX('Raw lists'!$B$2:$B$29,MATCH(L9,'Raw lists'!$B$2:$B$29,0))&" / ",""))&IF(M9="","",IFERROR(INDEX('Raw lists'!$B$2:$B$29,MATCH(M9,'Raw lists'!$B$2:$B$29,0))&" / ","")))-3)) | E9: =IF(LEN(IF(K9="","",IFERROR(INDEX('Raw lists'!$C$2:$C$23,MATCH(K9,'Raw lists'!$C$2:$C$23,0))&" / ",""))&IF(L9="","",IFERROR(INDEX('Raw lists'!$C$2:$C$23,MATCH(L9,'Raw lists'!$C$2:$C$23,0))&" / ",""))&IF(M9="","",IFERROR(INDEX('Raw lists'!$C$2:$C$23,MATCH(M9,'Raw lists'!$C$2:$C$23,0))&" / ","")))=0,"",LEFT(IF(K9="","",IFERROR(INDEX('Raw lists'!$C$2:$C$23,MATCH(K9,'Raw lists'!$C$2:$C$23,0))&" / ",""))&IF(L9="","",IFERROR(INDEX('Raw lists'!$C$2:$C$23,MATCH(L9,'Raw lists'!$C$2:$C$23,0))&" / ",""))&IF(M9="","",IFERROR(INDEX('Raw lists'!$C$2:$C$23,MATCH(M9,'Raw lists'!$C$2:$C$23,0))&" / ","")),LEN(IF(K9="","",IFERROR(INDEX('Raw lists'!$C$2:$C$23,MATCH(K9,'Raw lists'!$C$2:$C$23,0))&" / ",""))&IF(L9="","",IFERROR(INDEX('Raw lists'!$C$2:$C$23,MATCH(L9,'Raw lists'!$C$2:$C$23,0))&" / ",""))&IF(M9="","",IFERROR(INDEX('Raw lists'!$C$2:$C$23,MATCH(M9,'Raw lists'!$C$2:$C$23,0))&" / ","")))-3)) | F9: Core | G9: Solutions to independent subproblems where the relation breaks down. | H9: =COUNTIF(C9:E9,"?*") -> 1 | I9: =IF(H9=0,"None",IF(H9=3,"All three",IF(H9=1,"Only "&TRIM(IF(C9<>"","Gemini ","")&IF(D9<>"","RAKE ","")&IF(E9<>"","YAKE","")),SUBSTITUTE(TRIM(IF(C9<>"","Gemini ","")&IF(D9<>"","RAKE ","")&IF(E9<>"","YAKE",""))," "," + ")))) -> Only Gemini | K9: Base Case | L9: Base Cases
A10: 9 | B10: Original problem | C10: =IF(LEN(IF(K10="","",IFERROR(INDEX('Raw lists'!$A$2:$A$32,MATCH(K10,'Raw lists'!$A$2:$A$32,0))&" / ",""))&IF(L10="","",IFERROR(INDEX('Raw lists'!$A$2:$A$32,MATCH(L10,'Raw lists'!$A$2:$A$32,0))&" / ",""))&IF(M10="","",IFERROR(INDEX('Raw lists'!$A$2:$A$32,MATCH(M10,'Raw lists'!$A$2:$A$32,0))&" / ","")))=0,"",LEFT(IF(K10="","",IFERROR(INDEX('Raw lists'!$A$2:$A$32,MATCH(K10,'Raw lists'!$A$2:$A$32,0))&" / ",""))&IF(L10="","",IFERROR(INDEX('Raw lists'!$A$2:$A$32,MATCH(L10,'Raw lists'!$A$2:$A$32,0))&" / ",""))&IF(M10="","",IFERROR(INDEX('Raw lists'!$A$2:$A$32,MATCH(M10,'Raw lists'!$A$2:$A$32,0))&" / ","")),LEN(IF(K10="","",IFERROR(INDEX('Raw lists'!$A$2:$A$32,MATCH(K10,'Raw lists'!$A$2:$A$32,0))&" / ",""))&IF(L10="","",IFERROR(INDEX('Raw lists'!$A$2:$A$32,MATCH(L10,'Raw lists'!$A$2:$A$32,0))&" / ",""))&IF(M10="","",IFERROR(INDEX('Raw lists'!$A$2:$A$32,MATCH(M10,'Raw lists'!$A$2:$A$32,0))&" / ","")))-3)) | D10: =IF(LEN(IF(K10="","",IFERROR(INDEX('Raw lists'!$B$2:$B$29,MATCH(K10,'Raw lists'!$B$2:$B$29,0))&" / ",""))&IF(L10="","",IFERROR(INDEX('Raw lists'!$B$2:$B$29,MATCH(L10,'Raw lists'!$B$2:$B$29,0))&" / ",""))&IF(M10="","",IFERROR(INDEX('Raw lists'!$B$2:$B$29,MATCH(M10,'Raw lists'!$B$2:$B$29,0))&" / ","")))=0,"",LEFT(IF(K10="","",IFERROR(INDEX('Raw lists'!$B$2:$B$29,MATCH(K10,'Raw lists'!$B$2:$B$29,0))&" / ",""))&IF(L10="","",IFERROR(INDEX('Raw lists'!$B$2:$B$29,MATCH(L10,'Raw lists'!$B$2:$B$29,0))&" / ",""))&IF(M10="","",IFERROR(INDEX('Raw lists'!$B$2:$B$29,MATCH(M10,'Raw lists'!$B$2:$B$29,0))&" / ","")),LEN(IF(K10="","",IFERROR(INDEX('Raw lists'!$B$2:$B$29,MATCH(K10,'Raw lists'!$B$2:$B$29,0))&" / ",""))&IF(L10="","",IFERROR(INDEX('Raw lists'!$B$2:$B$29,MATCH(L10,'Raw lists'!$B$2:$B$29,0))&" / ",""))&IF(M10="","",IFERROR(INDEX('Raw lists'!$B$2:$B$29,MATCH(M10,'Raw lists'!$B$2:$B$29,0))&" / ","")))-3)) | E10: =IF(LEN(IF(K10="","",IFERROR(INDEX('Raw lists'!$C$2:$C$23,MATCH(K10,'Raw lists'!$C$2:$C$23,0))&" / ",""))&IF(L10="","",IFERROR(INDEX('Raw lists'!$C$2:$C$23,MATCH(L10,'Raw lists'!$C$2:$C$23,0))&" / ",""))&IF(M10="","",IFERROR(INDEX('Raw lists'!$C$2:$C$23,MATCH(M10,'Raw lists'!$C$2:$C$23,0))&" / ","")))=0,"",LEFT(IF(K10="","",IFERROR(INDEX('Raw lists'!$C$2:$C$23,MATCH(K10,'Raw lists'!$C$2:$C$23,0))&" / ",""))&IF(L10="","",IFERROR(INDEX('Raw lists'!$C$2:$C$23,MATCH(L10,'Raw lists'!$C$2:$C$23,0))&" / ",""))&IF(M10="","",IFERROR(INDEX('Raw lists'!$C$2:$C$23,MATCH(M10,'Raw lists'!$C$2:$C$23,0))&" / ","")),LEN(IF(K10="","",IFERROR(INDEX('Raw lists'!$C$2:$C$23,MATCH(K10,'Raw lists'!$C$2:$C$23,0))&" / ",""))&IF(L10="","",IFERROR(INDEX('Raw lists'!$C$2:$C$23,MATCH(L10,'Raw lists'!$C$2:$C$23,0))&" / ",""))&IF(M10="","",IFERROR(INDEX('Raw lists'!$C$2:$C$23,MATCH(M10,'Raw lists'!$C$2:$C$23,0))&" / ","")))-3)) -> Original Problem | F10: Core | G10: How to get the answer to the whole problem from subproblem solutions. | H10: =COUNTIF(C10:E10,"?*") -> 1 | I10: =IF(H10=0,"None",IF(H10=3,"All three",IF(H10=1,"Only "&TRIM(IF(C10<>"","Gemini ","")&IF(D10<>"","RAKE ","")&IF(E10<>"","YAKE","")),SUBSTITUTE(TRIM(IF(C10<>"","Gemini ","")&IF(D10<>"","RAKE ","")&IF(E10<>"","YAKE",""))," "," + ")))) -> Only YAKE | K10: Original Problem
A11: 10 | B11: Parent pointers | C11: =IF(LEN(IF(K11="","",IFERROR(INDEX('Raw lists'!$A$2:$A$32,MATCH(K11,'Raw lists'!$A$2:$A$32,0))&" / ",""))&IF(L11="","",IFERROR(INDEX('Raw lists'!$A$2:$A$32,MATCH(L11,'Raw lists'!$A$2:$A$32,0))&" / ",""))&IF(M11="","",IFERROR(INDEX('Raw lists'!$A$2:$A$32,MATCH(M11,'Raw lists'!$A$2:$A$32,0))&" / ","")))=0,"",LEFT(IF(K11="","",IFERROR(INDEX('Raw lists'!$A$2:$A$32,MATCH(K11,'Raw lists'!$A$2:$A$32,0))&" / ",""))&IF(L11="","",IFERROR(INDEX('Raw lists'!$A$2:$A$32,MATCH(L11,'Raw lists'!$A$2:$A$32,0))&" / ",""))&IF(M11="","",IFERROR(INDEX('Raw lists'!$A$2:$A$32,MATCH(M11,'Raw lists'!$A$2:$A$32,0))&" / ","")),LEN(IF(K11="","",IFERROR(INDEX('Raw lists'!$A$2:$A$32,MATCH(K11,'Raw lists'!$A$2:$A$32,0))&" / ",""))&IF(L11="","",IFERROR(INDEX('Raw lists'!$A$2:$A$32,MATCH(L11,'Raw lists'!$A$2:$A$32,0))&" / ",""))&IF(M11="","",IFERROR(INDEX('Raw lists'!$A$2:$A$32,MATCH(M11,'Raw lists'!$A$2:$A$32,0))&" / ","")))-3)) | D11: =IF(LEN(IF(K11="","",IFERROR(INDEX('Raw lists'!$B$2:$B$29,MATCH(K11,'Raw lists'!$B$2:$B$29,0))&" / ",""))&IF(L11="","",IFERROR(INDEX('Raw lists'!$B$2:$B$29,MATCH(L11,'Raw lists'!$B$2:$B$29,0))&" / ",""))&IF(M11="","",IFERROR(INDEX('Raw lists'!$B$2:$B$29,MATCH(M11,'Raw lists'!$B$2:$B$29,0))&" / ","")))=0,"",LEFT(IF(K11="","",IFERROR(INDEX('Raw lists'!$B$2:$B$29,MATCH(K11,'Raw lists'!$B$2:$B$29,0))&" / ",""))&IF(L11="","",IFERROR(INDEX('Raw lists'!$B$2:$B$29,MATCH(L11,'Raw lists'!$B$2:$B$29,0))&" / ",""))&IF(M11="","",IFERROR(INDEX('Raw lists'!$B$2:$B$29,MATCH(M11,'Raw lists'!$B$2:$B$29,0))&" / ","")),LEN(IF(K11="","",IFERROR(INDEX('Raw lists'!$B$2:$B$29,MATCH(K11,'Raw lists'!$B$2:$B$29,0))&" / ",""))&IF(L11="","",IFERROR(INDEX('Raw lists'!$B$2:$B$29,MATCH(L11,'Raw lists'!$B$2:$B$29,0))&" / ",""))&IF(M11="","",IFERROR(INDEX('Raw lists'!$B$2:$B$29,MATCH(M11,'Raw lists'!$B$2:$B$29,0))&" / ","")))-3)) | E11: =IF(LEN(IF(K11="","",IFERROR(INDEX('Raw lists'!$C$2:$C$23,MATCH(K11,'Raw lists'!$C$2:$C$23,0))&" / ",""))&IF(L11="","",IFERROR(INDEX('Raw lists'!$C$2:$C$23,MATCH(L11,'Raw lists'!$C$2:$C$23,0))&" / ",""))&IF(M11="","",IFERROR(INDEX('Raw lists'!$C$2:$C$23,MATCH(M11,'Raw lists'!$C$2:$C$23,0))&" / ","")))=0,"",LEFT(IF(K11="","",IFERROR(INDEX('Raw lists'!$C$2:$C$23,MATCH(K11,'Raw lists'!$C$2:$C$23,0))&" / ",""))&IF(L11="","",IFERROR(INDEX('Raw lists'!$C$2:$C$23,MATCH(L11,'Raw lists'!$C$2:$C$23,0))&" / ",""))&IF(M11="","",IFERROR(INDEX('Raw lists'!$C$2:$C$23,MATCH(M11,'Raw lists'!$C$2:$C$23,0))&" / ","")),LEN(IF(K11="","",IFERROR(INDEX('Raw lists'!$C$2:$C$23,MATCH(K11,'Raw lists'!$C$2:$C$23,0))&" / ",""))&IF(L11="","",IFERROR(INDEX('Raw lists'!$C$2:$C$23,MATCH(L11,'Raw lists'!$C$2:$C$23,0))&" / ",""))&IF(M11="","",IFERROR(INDEX('Raw lists'!$C$2:$C$23,MATCH(M11,'Raw lists'!$C$2:$C$23,0))&" / ","")))-3)) | F11: Core | G11: Remember the best choice per subproblem to recover the actual solution. | H11: =COUNTIF(C11:E11,"?*") -> 0 | I11: =IF(H11=0,"None",IF(H11=3,"All three",IF(H11=1,"Only "&TRIM(IF(C11<>"","Gemini ","")&IF(D11<>"","RAKE ","")&IF(E11<>"","YAKE","")),SUBSTITUTE(TRIM(IF(C11<>"","Gemini ","")&IF(D11<>"","RAKE ","")&IF(E11<>"","YAKE",""))," "," + ")))) -> None | K11: Parent Pointers
A12: 11 | B12: Time analysis | C12: =IF(LEN(IF(K12="","",IFERROR(INDEX('Raw lists'!$A$2:$A$32,MATCH(K12,'Raw lists'!$A$2:$A$32,0))&" / ",""))&IF(L12="","",IFERROR(INDEX('Raw lists'!$A$2:$A$32,MATCH(L12,'Raw lists'!$A$2:$A$32,0))&" / ",""))&IF(M12="","",IFERROR(INDEX('Raw lists'!$A$2:$A$32,MATCH(M12,'Raw lists'!$A$2:$A$32,0))&" / ","")))=0,"",LEFT(IF(K12="","",IFERROR(INDEX('Raw lists'!$A$2:$A$32,MATCH(K12,'Raw lists'!$A$2:$A$32,0))&" / ",""))&IF(L12="","",IFERROR(INDEX('Raw lists'!$A$2:$A$32,MATCH(L12,'Raw lists'!$A$2:$A$32,0))&" / ",""))&IF(M12="","",IFERROR(INDEX('Raw lists'!$A$2:$A$32,MATCH(M12,'Raw lists'!$A$2:$A$32,0))&" / ","")),LEN(IF(K12="","",IFERROR(INDEX('Raw lists'!$A$2:$A$32,MATCH(K12,'Raw lists'!$A$2:$A$32,0))&" / ",""))&IF(L12="","",IFERROR(INDEX('Raw lists'!$A$2:$A$32,MATCH(L12,'Raw lists'!$A$2:$A$32,0))&" / ",""))&IF(M12="","",IFERROR(INDEX('Raw lists'!$A$2:$A$32,MATCH(M12,'Raw lists'!$A$2:$A$32,0))&" / ","")))-3)) | D12: =IF(LEN(IF(K12="","",IFERROR(INDEX('Raw lists'!$B$2:$B$29,MATCH(K12,'Raw lists'!$B$2:$B$29,0))&" / ",""))&IF(L12="","",IFERROR(INDEX('Raw lists'!$B$2:$B$29,MATCH(L12,'Raw lists'!$B$2:$B$29,0))&" / ",""))&IF(M12="","",IFERROR(INDEX('Raw lists'!$B$2:$B$29,MATCH(M12,'Raw lists'!$B$2:$B$29,0))&" / ","")))=0,"",LEFT(IF(K12="","",IFERROR(INDEX('Raw lists'!$B$2:$B$29,MATCH(K12,'Raw lists'!$B$2:$B$29,0))&" / ",""))&IF(L12="","",IFERROR(INDEX('Raw lists'!$B$2:$B$29,MATCH(L12,'Raw lists'!$B$2:$B$29,0))&" / ",""))&IF(M12="","",IFERROR(INDEX('Raw lists'!$B$2:$B$29,MATCH(M12,'Raw lists'!$B$2:$B$29,0))&" / ","")),LEN(IF(K12="","",IFERROR(INDEX('Raw lists'!$B$2:$B$29,MATCH(K12,'Raw lists'!$B$2:$B$29,0))&" / ",""))&IF(L12="","",IFERROR(INDEX('Raw lists'!$B$2:$B$29,MATCH(L12,'Raw lists'!$B$2:$B$29,0))&" / ",""))&IF(M12="","",IFERROR(INDEX('Raw lists'!$B$2:$B$29,MATCH(M12,'Raw lists'!$B$2:$B$29,0))&" / ","")))-3)) | E12: =IF(LEN(IF(K12="","",IFERROR(INDEX('Raw lists'!$C$2:$C$23,MATCH(K12,'Raw lists'!$C$2:$C$23,0))&" / ",""))&IF(L12="","",IFERROR(INDEX('Raw lists'!$C$2:$C$23,MATCH(L12,'Raw lists'!$C$2:$C$23,0))&" / ",""))&IF(M12="","",IFERROR(INDEX('Raw lists'!$C$2:$C$23,MATCH(M12,'Raw lists'!$C$2:$C$23,0))&" / ","")))=0,"",LEFT(IF(K12="","",IFERROR(INDEX('Raw lists'!$C$2:$C$23,MATCH(K12,'Raw lists'!$C$2:$C$23,0))&" / ",""))&IF(L12="","",IFERROR(INDEX('Raw lists'!$C$2:$C$23,MATCH(L12,'Raw lists'!$C$2:$C$23,0))&" / ",""))&IF(M12="","",IFERROR(INDEX('Raw lists'!$C$2:$C$23,MATCH(M12,'Raw lists'!$C$2:$C$23,0))&" / ","")),LEN(IF(K12="","",IFERROR(INDEX('Raw lists'!$C$2:$C$23,MATCH(K12,'Raw lists'!$C$2:$C$23,0))&" / ",""))&IF(L12="","",IFERROR(INDEX('Raw lists'!$C$2:$C$23,MATCH(L12,'Raw lists'!$C$2:$C$23,0))&" / ",""))&IF(M12="","",IFERROR(INDEX('Raw lists'!$C$2:$C$23,MATCH(M12,'Raw lists'!$C$2:$C$23,0))&" / ","")))-3)) | F12: Core | G12: Total work over all subproblems: number of subproblems times work per subproblem. | H12: =COUNTIF(C12:E12,"?*") -> 0 | I12: =IF(H12=0,"None",IF(H12=3,"All three",IF(H12=1,"Only "&TRIM(IF(C12<>"","Gemini ","")&IF(D12<>"","RAKE ","")&IF(E12<>"","YAKE","")),SUBSTITUTE(TRIM(IF(C12<>"","Gemini ","")&IF(D12<>"","RAKE ","")&IF(E12<>"","YAKE",""))," "," + ")))) -> None | K12: Time Analysis
A13: 12 | B13: Memoization | C13: =IF(LEN(IF(K13="","",IFERROR(INDEX('Raw lists'!$A$2:$A$32,MATCH(K13,'Raw lists'!$A$2:$A$32,0))&" / ",""))&IF(L13="","",IFERROR(INDEX('Raw lists'!$A$2:$A$32,MATCH(L13,'Raw lists'!$A$2:$A$32,0))&" / ",""))&IF(M13="","",IFERROR(INDEX('Raw lists'!$A$2:$A$32,MATCH(M13,'Raw lists'!$A$2:$A$32,0))&" / ","")))=0,"",LEFT(IF(K13="","",IFERROR(INDEX('Raw lists'!$A$2:$A$32,MATCH(K13,'Raw lists'!$A$2:$A$32,0))&" / ",""))&IF(L13="","",IFERROR(INDEX('Raw lists'!$A$2:$A$32,MATCH(L13,'Raw lists'!$A$2:$A$32,0))&" / ",""))&IF(M13="","",IFERROR(INDEX('Raw lists'!$A$2:$A$32,MATCH(M13,'Raw lists'!$A$2:$A$32,0))&" / ","")),LEN(IF(K13="","",IFERROR(INDEX('Raw lists'!$A$2:$A$32,MATCH(K13,'Raw lists'!$A$2:$A$32,0))&" / ",""))&IF(L13="","",IFERROR(INDEX('Raw lists'!$A$2:$A$32,MATCH(L13,'Raw lists'!$A$2:$A$32,0))&" / ",""))&IF(M13="","",IFERROR(INDEX('Raw lists'!$A$2:$A$32,MATCH(M13,'Raw lists'!$A$2:$A$32,0))&" / ","")))-3)) | D13: =IF(LEN(IF(K13="","",IFERROR(INDEX('Raw lists'!$B$2:$B$29,MATCH(K13,'Raw lists'!$B$2:$B$29,0))&" / ",""))&IF(L13="","",IFERROR(INDEX('Raw lists'!$B$2:$B$29,MATCH(L13,'Raw lists'!$B$2:$B$29,0))&" / ",""))&IF(M13="","",IFERROR(INDEX('Raw lists'!$B$2:$B$29,MATCH(M13,'Raw lists'!$B$2:$B$29,0))&" / ","")))=0,"",LEFT(IF(K13="","",IFERROR(INDEX('Raw lists'!$B$2:$B$29,MATCH(K13,'Raw lists'!$B$2:$B$29,0))&" / ",""))&IF(L13="","",IFERROR(INDEX('Raw lists'!$B$2:$B$29,MATCH(L13,'Raw lists'!$B$2:$B$29,0))&" / ",""))&IF(M13="","",IFERROR(INDEX('Raw lists'!$B$2:$B$29,MATCH(M13,'Raw lists'!$B$2:$B$29,0))&" / ","")),LEN(IF(K13="","",IFERROR(INDEX('Raw lists'!$B$2:$B$29,MATCH(K13,'Raw lists'!$B$2:$B$29,0))&" / ",""))&IF(L13="","",IFERROR(INDEX('Raw lists'!$B$2:$B$29,MATCH(L13,'Raw lists'!$B$2:$B$29,0))&" / ",""))&IF(M13="","",IFERROR(INDEX('Raw lists'!$B$2:$B$29,MATCH(M13,'Raw lists'!$B$2:$B$29,0))&" / ","")))-3)) | E13: =IF(LEN(IF(K13="","",IFERROR(INDEX('Raw lists'!$C$2:$C$23,MATCH(K13,'Raw lists'!$C$2:$C$23,0))&" / ",""))&IF(L13="","",IFERROR(INDEX('Raw lists'!$C$2:$C$23,MATCH(L13,'Raw lists'!$C$2:$C$23,0))&" / ",""))&IF(M13="","",IFERROR(INDEX('Raw lists'!$C$2:$C$23,MATCH(M13,'Raw lists'!$C$2:$C$23,0))&" / ","")))=0,"",LEFT(IF(K13="","",IFERROR(INDEX('Raw lists'!$C$2:$C$23,MATCH(K13,'Raw lists'!$C$2:$C$23,0))&" / ",""))&IF(L13="","",IFERROR(INDEX('Raw lists'!$C$2:$C$23,MATCH(L13,'Raw lists'!$C$2:$C$23,0))&" / ",""))&IF(M13="","",IFERROR(INDEX('Raw lists'!$C$2:$C$23,MATCH(M13,'Raw lists'!$C$2:$C$23,0))&" / ","")),LEN(IF(K13="","",IFERROR(INDEX('Raw lists'!$C$2:$C$23,MATCH(K13,'Raw lists'!$C$2:$C$23,0))&" / ",""))&IF(L13="","",IFERROR(INDEX('Raw lists'!$C$2:$C$23,MATCH(L13,'Raw lists'!$C$2:$C$23,0))&" / ",""))&IF(M13="","",IFERROR(INDEX('Raw lists'!$C$2:$C$23,MATCH(M13,'Raw lists'!$C$2:$C$23,0))&" / ","")))-3)) | F13: Core | G13: Store computed subproblem results in a memo and reuse them during recursion. | H13: =COUNTIF(C13:E13,"?*") -> 0 | I13: =IF(H13=0,"None",IF(H13=3,"All three",IF(H13=1,"Only "&TRIM(IF(C13<>"","Gemini ","")&IF(D13<>"","RAKE ","")&IF(E13<>"","YAKE","")),SUBSTITUTE(TRIM(IF(C13<>"","Gemini ","")&IF(D13<>"","RAKE ","")&IF(E13<>"","YAKE",""))," "," + ")))) -> None | K13: Memoization | L13: Memo
A14: 13 | B14: Bottom-up | C14: =IF(LEN(IF(K14="","",IFERROR(INDEX('Raw lists'!$A$2:$A$32,MATCH(K14,'Raw lists'!$A$2:$A$32,0))&" / ",""))&IF(L14="","",IFERROR(INDEX('Raw lists'!$A$2:$A$32,MATCH(L14,'Raw lists'!$A$2:$A$32,0))&" / ",""))&IF(M14="","",IFERROR(INDEX('Raw lists'!$A$2:$A$32,MATCH(M14,'Raw lists'!$A$2:$A$32,0))&" / ","")))=0,"",LEFT(IF(K14="","",IFERROR(INDEX('Raw lists'!$A$2:$A$32,MATCH(K14,'Raw lists'!$A$2:$A$32,0))&" / ",""))&IF(L14="","",IFERROR(INDEX('Raw lists'!$A$2:$A$32,MATCH(L14,'Raw lists'!$A$2:$A$32,0))&" / ",""))&IF(M14="","",IFERROR(INDEX('Raw lists'!$A$2:$A$32,MATCH(M14,'Raw lists'!$A$2:$A$32,0))&" / ","")),LEN(IF(K14="","",IFERROR(INDEX('Raw lists'!$A$2:$A$32,MATCH(K14,'Raw lists'!$A$2:$A$32,0))&" / ",""))&IF(L14="","",IFERROR(INDEX('Raw lists'!$A$2:$A$32,MATCH(L14,'Raw lists'!$A$2:$A$32,0))&" / ",""))&IF(M14="","",IFERROR(INDEX('Raw lists'!$A$2:$A$32,MATCH(M14,'Raw lists'!$A$2:$A$32,0))&" / ","")))-3)) | D14: =IF(LEN(IF(K14="","",IFERROR(INDEX('Raw lists'!$B$2:$B$29,MATCH(K14,'Raw lists'!$B$2:$B$29,0))&" / ",""))&IF(L14="","",IFERROR(INDEX('Raw lists'!$B$2:$B$29,MATCH(L14,'Raw lists'!$B$2:$B$29,0))&" / ",""))&IF(M14="","",IFERROR(INDEX('Raw lists'!$B$2:$B$29,MATCH(M14,'Raw lists'!$B$2:$B$29,0))&" / ","")))=0,"",LEFT(IF(K14="","",IFERROR(INDEX('Raw lists'!$B$2:$B$29,MATCH(K14,'Raw lists'!$B$2:$B$29,0))&" / ",""))&IF(L14="","",IFERROR(INDEX('Raw lists'!$B$2:$B$29,MATCH(L14,'Raw lists'!$B$2:$B$29,0))&" / ",""))&IF(M14="","",IFERROR(INDEX('Raw lists'!$B$2:$B$29,MATCH(M14,'Raw lists'!$B$2:$B$29,0))&" / ","")),LEN(IF(K14="","",IFERROR(INDEX('Raw lists'!$B$2:$B$29,MATCH(K14,'Raw lists'!$B$2:$B$29,0))&" / ",""))&IF(L14="","",IFERROR(INDEX('Raw lists'!$B$2:$B$29,MATCH(L14,'Raw lists'!$B$2:$B$29,0))&" / ",""))&IF(M14="","",IFERROR(INDEX('Raw lists'!$B$2:$B$29,MATCH(M14,'Raw lists'!$B$2:$B$29,0))&" / ","")))-3)) | E14: =IF(LEN(IF(K14="","",IFERROR(INDEX('Raw lists'!$C$2:$C$23,MATCH(K14,'Raw lists'!$C$2:$C$23,0))&" / ",""))&IF(L14="","",IFERROR(INDEX('Raw lists'!$C$2:$C$23,MATCH(L14,'Raw lists'!$C$2:$C$23,0))&" / ",""))&IF(M14="","",IFERROR(INDEX('Raw lists'!$C$2:$C$23,MATCH(M14,'Raw lists'!$C$2:$C$23,0))&" / ","")))=0,"",LEFT(IF(K14="","",IFERROR(INDEX('Raw lists'!$C$2:$C$23,MATCH(K14,'Raw lists'!$C$2:$C$23,0))&" / ",""))&IF(L14="","",IFERROR(INDEX('Raw lists'!$C$2:$C$23,MATCH(L14,'Raw lists'!$C$2:$C$23,0))&" / ",""))&IF(M14="","",IFERROR(INDEX('Raw lists'!$C$2:$C$23,MATCH(M14,'Raw lists'!$C$2:$C$23,0))&" / ","")),LEN(IF(K14="","",IFERROR(INDEX('Raw lists'!$C$2:$C$23,MATCH(K14,'Raw lists'!$C$2:$C$23,0))&" / ",""))&IF(L14="","",IFERROR(INDEX('Raw lists'!$C$2:$C$23,MATCH(L14,'Raw lists'!$C$2:$C$23,0))&" / ",""))&IF(M14="","",IFERROR(INDEX('Raw lists'!$C$2:$C$23,MATCH(M14,'Raw lists'!$C$2:$C$23,0))&" / ","")))-3)) | F14: Core | G14: Solve all subproblems in topological order. | H14: =COUNTIF(C14:E14,"?*") -> 0 | I14: =IF(H14=0,"None",IF(H14=3,"All three",IF(H14=1,"Only "&TRIM(IF(C14<>"","Gemini ","")&IF(D14<>"","RAKE ","")&IF(E14<>"","YAKE","")),SUBSTITUTE(TRIM(IF(C14<>"","Gemini ","")&IF(D14<>"","RAKE ","")&IF(E14<>"","YAKE",""))," "," + ")))) -> None | K14: Bottom Up
A15: 14 | B15: Top-down (reachable subproblems) | C15: =IF(LEN(IF(K15="","",IFERROR(INDEX('Raw lists'!$A$2:$A$32,MATCH(K15,'Raw lists'!$A$2:$A$32,0))&" / ",""))&IF(L15="","",IFERROR(INDEX('Raw lists'!$A$2:$A$32,MATCH(L15,'Raw lists'!$A$2:$A$32,0))&" / ",""))&IF(M15="","",IFERROR(INDEX('Raw lists'!$A$2:$A$32,MATCH(M15,'Raw lists'!$A$2:$A$32,0))&" / ","")))=0,"",LEFT(IF(K15="","",IFERROR(INDEX('Raw lists'!$A$2:$A$32,MATCH(K15,'Raw lists'!$A$2:$A$32,0))&" / ",""))&IF(L15="","",IFERROR(INDEX('Raw lists'!$A$2:$A$32,MATCH(L15,'Raw lists'!$A$2:$A$32,0))&" / ",""))&IF(M15="","",IFERROR(INDEX('Raw lists'!$A$2:$A$32,MATCH(M15,'Raw lists'!$A$2:$A$32,0))&" / ","")),LEN(IF(K15="","",IFERROR(INDEX('Raw lists'!$A$2:$A$32,MATCH(K15,'Raw lists'!$A$2:$A$32,0))&" / ",""))&IF(L15="","",IFERROR(INDEX('Raw lists'!$A$2:$A$32,MATCH(L15,'Raw lists'!$A$2:$A$32,0))&" / ",""))&IF(M15="","",IFERROR(INDEX('Raw lists'!$A$2:$A$32,MATCH(M15,'Raw lists'!$A$2:$A$32,0))&" / ","")))-3)) -> Reachable Subproblems / Solve Only Reachable | D15: =IF(LEN(IF(K15="","",IFERROR(INDEX('Raw lists'!$B$2:$B$29,MATCH(K15,'Raw lists'!$B$2:$B$29,0))&" / ",""))&IF(L15="","",IFERROR(INDEX('Raw lists'!$B$2:$B$29,MATCH(L15,'Raw lists'!$B$2:$B$29,0))&" / ",""))&IF(M15="","",IFERROR(INDEX('Raw lists'!$B$2:$B$29,MATCH(M15,'Raw lists'!$B$2:$B$29,0))&" / ","")))=0,"",LEFT(IF(K15="","",IFERROR(INDEX('Raw lists'!$B$2:$B$29,MATCH(K15,'Raw lists'!$B$2:$B$29,0))&" / ",""))&IF(L15="","",IFERROR(INDEX('Raw lists'!$B$2:$B$29,MATCH(L15,'Raw lists'!$B$2:$B$29,0))&" / ",""))&IF(M15="","",IFERROR(INDEX('Raw lists'!$B$2:$B$29,MATCH(M15,'Raw lists'!$B$2:$B$29,0))&" / ","")),LEN(IF(K15="","",IFERROR(INDEX('Raw lists'!$B$2:$B$29,MATCH(K15,'Raw lists'!$B$2:$B$29,0))&" / ",""))&IF(L15="","",IFERROR(INDEX('Raw lists'!$B$2:$B$29,MATCH(L15,'Raw lists'!$B$2:$B$29,0))&" / ",""))&IF(M15="","",IFERROR(INDEX('Raw lists'!$B$2:$B$29,MATCH(M15,'Raw lists'!$B$2:$B$29,0))&" / ","")))-3)) | E15: =IF(LEN(IF(K15="","",IFERROR(INDEX('Raw lists'!$C$2:$C$23,MATCH(K15,'Raw lists'!$C$2:$C$23,0))&" / ",""))&IF(L15="","",IFERROR(INDEX('Raw lists'!$C$2:$C$23,MATCH(L15,'Raw lists'!$C$2:$C$23,0))&" / ",""))&IF(M15="","",IFERROR(INDEX('Raw lists'!$C$2:$C$23,MATCH(M15,'Raw lists'!$C$2:$C$23,0))&" / ","")))=0,"",LEFT(IF(K15="","",IFERROR(INDEX('Raw lists'!$C$2:$C$23,MATCH(K15,'Raw lists'!$C$2:$C$23,0))&" / ",""))&IF(L15="","",IFERROR(INDEX('Raw lists'!$C$2:$C$23,MATCH(L15,'Raw lists'!$C$2:$C$23,0))&" / ",""))&IF(M15="","",IFERROR(INDEX('Raw lists'!$C$2:$C$23,MATCH(M15,'Raw lists'!$C$2:$C$23,0))&" / ","")),LEN(IF(K15="","",IFERROR(INDEX('Raw lists'!$C$2:$C$23,MATCH(K15,'Raw lists'!$C$2:$C$23,0))&" / ",""))&IF(L15="","",IFERROR(INDEX('Raw lists'!$C$2:$C$23,MATCH(L15,'Raw lists'!$C$2:$C$23,0))&" / ",""))&IF(M15="","",IFERROR(INDEX('Raw lists'!$C$2:$C$23,MATCH(M15,'Raw lists'!$C$2:$C$23,0))&" / ","")))-3)) | F15: Core | G15: Recurse and solve only the subproblems that are actually reached. | H15: =COUNTIF(C15:E15,"?*") -> 1 | I15: =IF(H15=0,"None",IF(H15=3,"All three",IF(H15=1,"Only "&TRIM(IF(C15<>"","Gemini ","")&IF(D15<>"","RAKE ","")&IF(E15<>"","YAKE","")),SUBSTITUTE(TRIM(IF(C15<>"","Gemini ","")&IF(D15<>"","RAKE ","")&IF(E15<>"","YAKE",""))," "," + ")))) -> Only Gemini | K15: Top Down | L15: Reachable Subproblems | M15: Solve Only Reachable
A16: 15 | B16: Rod Cutting | C16: =IF(LEN(IF(K16="","",IFERROR(INDEX('Raw lists'!$A$2:$A$32,MATCH(K16,'Raw lists'!$A$2:$A$32,0))&" / ",""))&IF(L16="","",IFERROR(INDEX('Raw lists'!$A$2:$A$32,MATCH(L16,'Raw lists'!$A$2:$A$32,0))&" / ",""))&IF(M16="","",IFERROR(INDEX('Raw lists'!$A$2:$A$32,MATCH(M16,'Raw lists'!$A$2:$A$32,0))&" / ","")))=0,"",LEFT(IF(K16="","",IFERROR(INDEX('Raw lists'!$A$2:$A$32,MATCH(K16,'Raw lists'!$A$2:$A$32,0))&" / ",""))&IF(L16="","",IFERROR(INDEX('Raw lists'!$A$2:$A$32,MATCH(L16,'Raw lists'!$A$2:$A$32,0))&" / ",""))&IF(M16="","",IFERROR(INDEX('Raw lists'!$A$2:$A$32,MATCH(M16,'Raw lists'!$A$2:$A$32,0))&" / ","")),LEN(IF(K16="","",IFERROR(INDEX('Raw lists'!$A$2:$A$32,MATCH(K16,'Raw lists'!$A$2:$A$32,0))&" / ",""))&IF(L16="","",IFERROR(INDEX('Raw lists'!$A$2:$A$32,MATCH(L16,'Raw lists'!$A$2:$A$32,0))&" / ",""))&IF(M16="","",IFERROR(INDEX('Raw lists'!$A$2:$A$32,MATCH(M16,'Raw lists'!$A$2:$A$32,0))&" / ","")))-3)) -> Rod Cutting / Cutting Rod | D16: =IF(LEN(IF(K16="","",IFERROR(INDEX('Raw lists'!$B$2:$B$29,MATCH(K16,'Raw lists'!$B$2:$B$29,0))&" / ",""))&IF(L16="","",IFERROR(INDEX('Raw lists'!$B$2:$B$29,MATCH(L16,'Raw lists'!$B$2:$B$29,0))&" / ",""))&IF(M16="","",IFERROR(INDEX('Raw lists'!$B$2:$B$29,MATCH(M16,'Raw lists'!$B$2:$B$29,0))&" / ","")))=0,"",LEFT(IF(K16="","",IFERROR(INDEX('Raw lists'!$B$2:$B$29,MATCH(K16,'Raw lists'!$B$2:$B$29,0))&" / ",""))&IF(L16="","",IFERROR(INDEX('Raw lists'!$B$2:$B$29,MATCH(L16,'Raw lists'!$B$2:$B$29,0))&" / ",""))&IF(M16="","",IFERROR(INDEX('Raw lists'!$B$2:$B$29,MATCH(M16,'Raw lists'!$B$2:$B$29,0))&" / ","")),LEN(IF(K16="","",IFERROR(INDEX('Raw lists'!$B$2:$B$29,MATCH(K16,'Raw lists'!$B$2:$B$29,0))&" / ",""))&IF(L16="","",IFERROR(INDEX('Raw lists'!$B$2:$B$29,MATCH(L16,'Raw lists'!$B$2:$B$29,0))&" / ",""))&IF(M16="","",IFERROR(INDEX('Raw lists'!$B$2:$B$29,MATCH(M16,'Raw lists'!$B$2:$B$29,0))&" / ","")))-3)) | E16: =IF(LEN(IF(K16="","",IFERROR(INDEX('Raw lists'!$C$2:$C$23,MATCH(K16,'Raw lists'!$C$2:$C$23,0))&" / ",""))&IF(L16="","",IFERROR(INDEX('Raw lists'!$C$2:$C$23,MATCH(L16,'Raw lists'!$C$2:$C$23,0))&" / ",""))&IF(M16="","",IFERROR(INDEX('Raw lists'!$C$2:$C$23,MATCH(M16,'Raw lists'!$C$2:$C$23,0))&" / ","")))=0,"",LEFT(IF(K16="","",IFERROR(INDEX('Raw lists'!$C$2:$C$23,MATCH(K16,'Raw lists'!$C$2:$C$23,0))&" / ",""))&IF(L16="","",IFERROR(INDEX('Raw lists'!$C$2:$C$23,MATCH(L16,'Raw lists'!$C$2:$C$23,0))&" / ",""))&IF(M16="","",IFERROR(INDEX('Raw lists'!$C$2:$C$23,MATCH(M16,'Raw lists'!$C$2:$C$23,0))&" / ","")),LEN(IF(K16="","",IFERROR(INDEX('Raw lists'!$C$2:$C$23,MATCH(K16,'Raw lists'!$C$2:$C$23,0))&" / ",""))&IF(L16="","",IFERROR(INDEX('Raw lists'!$C$2:$C$23,MATCH(L16,'Raw lists'!$C$2:$C$23,0))&" / ",""))&IF(M16="","",IFERROR(INDEX('Raw lists'!$C$2:$C$23,MATCH(M16,'Raw lists'!$C$2:$C$23,0))&" / ","")))-3)) -> Rod Cutting / Cutting Rod | F16: Core | G16: Cut a rod of length L into pieces to maximize the total value. | H16: =COUNTIF(C16:E16,"?*") -> 2 | I16: =IF(H16=0,"None",IF(H16=3,"All three",IF(H16=1,"Only "&TRIM(IF(C16<>"","Gemini ","")&IF(D16<>"","RAKE ","")&IF(E16<>"","YAKE","")),SUBSTITUTE(TRIM(IF(C16<>"","Gemini ","")&IF(D16<>"","RAKE ","")&IF(E16<>"","YAKE",""))," "," + ")))) -> Gemini + YAKE | K16: Rod Cutting | L16: Cutting Rod
A17: 16 | B17: Greedy approach (counterexample) | C17: =IF(LEN(IF(K17="","",IFERROR(INDEX('Raw lists'!$A$2:$A$32,MATCH(K17,'Raw lists'!$A$2:$A$32,0))&" / ",""))&IF(L17="","",IFERROR(INDEX('Raw lists'!$A$2:$A$32,MATCH(L17,'Raw lists'!$A$2:$A$32,0))&" / ",""))&IF(M17="","",IFERROR(INDEX('Raw lists'!$A$2:$A$32,MATCH(M17,'Raw lists'!$A$2:$A$32,0))&" / ","")))=0,"",LEFT(IF(K17="","",IFERROR(INDEX('Raw lists'!$A$2:$A$32,MATCH(K17,'Raw lists'!$A$2:$A$32,0))&" / ",""))&IF(L17="","",IFERROR(INDEX('Raw lists'!$A$2:$A$32,MATCH(L17,'Raw lists'!$A$2:$A$32,0))&" / ",""))&IF(M17="","",IFERROR(INDEX('Raw lists'!$A$2:$A$32,MATCH(M17,'Raw lists'!$A$2:$A$32,0))&" / ","")),LEN(IF(K17="","",IFERROR(INDEX('Raw lists'!$A$2:$A$32,MATCH(K17,'Raw lists'!$A$2:$A$32,0))&" / ",""))&IF(L17="","",IFERROR(INDEX('Raw lists'!$A$2:$A$32,MATCH(L17,'Raw lists'!$A$2:$A$32,0))&" / ",""))&IF(M17="","",IFERROR(INDEX('Raw lists'!$A$2:$A$32,MATCH(M17,'Raw lists'!$A$2:$A$32,0))&" / ","")))-3)) | D17: =IF(LEN(IF(K17="","",IFERROR(INDEX('Raw lists'!$B$2:$B$29,MATCH(K17,'Raw lists'!$B$2:$B$29,0))&" / ",""))&IF(L17="","",IFERROR(INDEX('Raw lists'!$B$2:$B$29,MATCH(L17,'Raw lists'!$B$2:$B$29,0))&" / ",""))&IF(M17="","",IFERROR(INDEX('Raw lists'!$B$2:$B$29,MATCH(M17,'Raw lists'!$B$2:$B$29,0))&" / ","")))=0,"",LEFT(IF(K17="","",IFERROR(INDEX('Raw lists'!$B$2:$B$29,MATCH(K17,'Raw lists'!$B$2:$B$29,0))&" / ",""))&IF(L17="","",IFERROR(INDEX('Raw lists'!$B$2:$B$29,MATCH(L17,'Raw lists'!$B$2:$B$29,0))&" / ",""))&IF(M17="","",IFERROR(INDEX('Raw lists'!$B$2:$B$29,MATCH(M17,'Raw lists'!$B$2:$B$29,0))&" / ","")),LEN(IF(K17="","",IFERROR(INDEX('Raw lists'!$B$2:$B$29,MATCH(K17,'Raw lists'!$B$2:$B$29,0))&" / ",""))&IF(L17="","",IFERROR(INDEX('Raw lists'!$B$2:$B$29,MATCH(L17,'Raw lists'!$B$2:$B$29,0))&" / ",""))&IF(M17="","",IFERROR(INDEX('Raw lists'!$B$2:$B$29,MATCH(M17,'Raw lists'!$B$2:$B$29,0))&" / ","")))-3)) | E17: =IF(LEN(IF(K17="","",IFERROR(INDEX('Raw lists'!$C$2:$C$23,MATCH(K17,'Raw lists'!$C$2:$C$23,0))&" / ",""))&IF(L17="","",IFERROR(INDEX('Raw lists'!$C$2:$C$23,MATCH(L17,'Raw lists'!$C$2:$C$23,0))&" / ",""))&IF(M17="","",IFERROR(INDEX('Raw lists'!$C$2:$C$23,MATCH(M17,'Raw lists'!$C$2:$C$23,0))&" / ","")))=0,"",LEFT(IF(K17="","",IFERROR(INDEX('Raw lists'!$C$2:$C$23,MATCH(K17,'Raw lists'!$C$2:$C$23,0))&" / ",""))&IF(L17="","",IFERROR(INDEX('Raw lists'!$C$2:$C$23,MATCH(L17,'Raw lists'!$C$2:$C$23,0))&" / ",""))&IF(M17="","",IFERROR(INDEX('Raw lists'!$C$2:$C$23,MATCH(M17,'Raw lists'!$C$2:$C$23,0))&" / ","")),LEN(IF(K17="","",IFERROR(INDEX('Raw lists'!$C$2:$C$23,MATCH(K17,'Raw lists'!$C$2:$C$23,0))&" / ",""))&IF(L17="","",IFERROR(INDEX('Raw lists'!$C$2:$C$23,MATCH(L17,'Raw lists'!$C$2:$C$23,0))&" / ",""))&IF(M17="","",IFERROR(INDEX('Raw lists'!$C$2:$C$23,MATCH(M17,'Raw lists'!$C$2:$C$23,0))&" / ","")))-3)) | F17: Core | G17: Taking the best value per unit length first is not optimal for Rod Cutting. | H17: =COUNTIF(C17:E17,"?*") -> 0 | I17: =IF(H17=0,"None",IF(H17=3,"All three",IF(H17=1,"Only "&TRIM(IF(C17<>"","Gemini ","")&IF(D17<>"","RAKE ","")&IF(E17<>"","YAKE","")),SUBSTITUTE(TRIM(IF(C17<>"","Gemini ","")&IF(D17<>"","RAKE ","")&IF(E17<>"","YAKE",""))," "," + ")))) -> None | K17: Greedy
A18: 17 | B18: Optimization problem | C18: =IF(LEN(IF(K18="","",IFERROR(INDEX('Raw lists'!$A$2:$A$32,MATCH(K18,'Raw lists'!$A$2:$A$32,0))&" / ",""))&IF(L18="","",IFERROR(INDEX('Raw lists'!$A$2:$A$32,MATCH(L18,'Raw lists'!$A$2:$A$32,0))&" / ",""))&IF(M18="","",IFERROR(INDEX('Raw lists'!$A$2:$A$32,MATCH(M18,'Raw lists'!$A$2:$A$32,0))&" / ","")))=0,"",LEFT(IF(K18="","",IFERROR(INDEX('Raw lists'!$A$2:$A$32,MATCH(K18,'Raw lists'!$A$2:$A$32,0))&" / ",""))&IF(L18="","",IFERROR(INDEX('Raw lists'!$A$2:$A$32,MATCH(L18,'Raw lists'!$A$2:$A$32,0))&" / ",""))&IF(M18="","",IFERROR(INDEX('Raw lists'!$A$2:$A$32,MATCH(M18,'Raw lists'!$A$2:$A$32,0))&" / ","")),LEN(IF(K18="","",IFERROR(INDEX('Raw lists'!$A$2:$A$32,MATCH(K18,'Raw lists'!$A$2:$A$32,0))&" / ",""))&IF(L18="","",IFERROR(INDEX('Raw lists'!$A$2:$A$32,MATCH(L18,'Raw lists'!$A$2:$A$32,0))&" / ",""))&IF(M18="","",IFERROR(INDEX('Raw lists'!$A$2:$A$32,MATCH(M18,'Raw lists'!$A$2:$A$32,0))&" / ","")))-3)) | D18: =IF(LEN(IF(K18="","",IFERROR(INDEX('Raw lists'!$B$2:$B$29,MATCH(K18,'Raw lists'!$B$2:$B$29,0))&" / ",""))&IF(L18="","",IFERROR(INDEX('Raw lists'!$B$2:$B$29,MATCH(L18,'Raw lists'!$B$2:$B$29,0))&" / ",""))&IF(M18="","",IFERROR(INDEX('Raw lists'!$B$2:$B$29,MATCH(M18,'Raw lists'!$B$2:$B$29,0))&" / ","")))=0,"",LEFT(IF(K18="","",IFERROR(INDEX('Raw lists'!$B$2:$B$29,MATCH(K18,'Raw lists'!$B$2:$B$29,0))&" / ",""))&IF(L18="","",IFERROR(INDEX('Raw lists'!$B$2:$B$29,MATCH(L18,'Raw lists'!$B$2:$B$29,0))&" / ",""))&IF(M18="","",IFERROR(INDEX('Raw lists'!$B$2:$B$29,MATCH(M18,'Raw lists'!$B$2:$B$29,0))&" / ","")),LEN(IF(K18="","",IFERROR(INDEX('Raw lists'!$B$2:$B$29,MATCH(K18,'Raw lists'!$B$2:$B$29,0))&" / ",""))&IF(L18="","",IFERROR(INDEX('Raw lists'!$B$2:$B$29,MATCH(L18,'Raw lists'!$B$2:$B$29,0))&" / ",""))&IF(M18="","",IFERROR(INDEX('Raw lists'!$B$2:$B$29,MATCH(M18,'Raw lists'!$B$2:$B$29,0))&" / ","")))-3)) | E18: =IF(LEN(IF(K18="","",IFERROR(INDEX('Raw lists'!$C$2:$C$23,MATCH(K18,'Raw lists'!$C$2:$C$23,0))&" / ",""))&IF(L18="","",IFERROR(INDEX('Raw lists'!$C$2:$C$23,MATCH(L18,'Raw lists'!$C$2:$C$23,0))&" / ",""))&IF(M18="","",IFERROR(INDEX('Raw lists'!$C$2:$C$23,MATCH(M18,'Raw lists'!$C$2:$C$23,0))&" / ","")))=0,"",LEFT(IF(K18="","",IFERROR(INDEX('Raw lists'!$C$2:$C$23,MATCH(K18,'Raw lists'!$C$2:$C$23,0))&" / ",""))&IF(L18="","",IFERROR(INDEX('Raw lists'!$C$2:$C$23,MATCH(L18,'Raw lists'!$C$2:$C$23,0))&" / ",""))&IF(M18="","",IFERROR(INDEX('Raw lists'!$C$2:$C$23,MATCH(M18,'Raw lists'!$C$2:$C$23,0))&" / ","")),LEN(IF(K18="","",IFERROR(INDEX('Raw lists'!$C$2:$C$23,MATCH(K18,'Raw lists'!$C$2:$C$23,0))&" / ",""))&IF(L18="","",IFERROR(INDEX('Raw lists'!$C$2:$C$23,MATCH(L18,'Raw lists'!$C$2:$C$23,0))&" / ",""))&IF(M18="","",IFERROR(INDEX('Raw lists'!$C$2:$C$23,MATCH(M18,'Raw lists'!$C$2:$C$23,0))&" / ","")))-3)) | F18: Core | G18: A problem that asks for the best value, such as a maximum. | H18: =COUNTIF(C18:E18,"?*") -> 0 | I18: =IF(H18=0,"None",IF(H18=3,"All three",IF(H18=1,"Only "&TRIM(IF(C18<>"","Gemini ","")&IF(D18<>"","RAKE ","")&IF(E18<>"","YAKE","")),SUBSTITUTE(TRIM(IF(C18<>"","Gemini ","")&IF(D18<>"","RAKE ","")&IF(E18<>"","YAKE",""))," "," + ")))) -> None | K18: Optimization Problem
A19: 18 | B19: Subset Sum | C19: =IF(LEN(IF(K19="","",IFERROR(INDEX('Raw lists'!$A$2:$A$32,MATCH(K19,'Raw lists'!$A$2:$A$32,0))&" / ",""))&IF(L19="","",IFERROR(INDEX('Raw lists'!$A$2:$A$32,MATCH(L19,'Raw lists'!$A$2:$A$32,0))&" / ",""))&IF(M19="","",IFERROR(INDEX('Raw lists'!$A$2:$A$32,MATCH(M19,'Raw lists'!$A$2:$A$32,0))&" / ","")))=0,"",LEFT(IF(K19="","",IFERROR(INDEX('Raw lists'!$A$2:$A$32,MATCH(K19,'Raw lists'!$A$2:$A$32,0))&" / ",""))&IF(L19="","",IFERROR(INDEX('Raw lists'!$A$2:$A$32,MATCH(L19,'Raw lists'!$A$2:$A$32,0))&" / ",""))&IF(M19="","",IFERROR(INDEX('Raw lists'!$A$2:$A$32,MATCH(M19,'Raw lists'!$A$2:$A$32,0))&" / ","")),LEN(IF(K19="","",IFERROR(INDEX('Raw lists'!$A$2:$A$32,MATCH(K19,'Raw lists'!$A$2:$A$32,0))&" / ",""))&IF(L19="","",IFERROR(INDEX('Raw lists'!$A$2:$A$32,MATCH(L19,'Raw lists'!$A$2:$A$32,0))&" / ",""))&IF(M19="","",IFERROR(INDEX('Raw lists'!$A$2:$A$32,MATCH(M19,'Raw lists'!$A$2:$A$32,0))&" / ","")))-3)) -> Subset Sum | D19: =IF(LEN(IF(K19="","",IFERROR(INDEX('Raw lists'!$B$2:$B$29,MATCH(K19,'Raw lists'!$B$2:$B$29,0))&" / ",""))&IF(L19="","",IFERROR(INDEX('Raw lists'!$B$2:$B$29,MATCH(L19,'Raw lists'!$B$2:$B$29,0))&" / ",""))&IF(M19="","",IFERROR(INDEX('Raw lists'!$B$2:$B$29,MATCH(M19,'Raw lists'!$B$2:$B$29,0))&" / ","")))=0,"",LEFT(IF(K19="","",IFERROR(INDEX('Raw lists'!$B$2:$B$29,MATCH(K19,'Raw lists'!$B$2:$B$29,0))&" / ",""))&IF(L19="","",IFERROR(INDEX('Raw lists'!$B$2:$B$29,MATCH(L19,'Raw lists'!$B$2:$B$29,0))&" / ",""))&IF(M19="","",IFERROR(INDEX('Raw lists'!$B$2:$B$29,MATCH(M19,'Raw lists'!$B$2:$B$29,0))&" / ","")),LEN(IF(K19="","",IFERROR(INDEX('Raw lists'!$B$2:$B$29,MATCH(K19,'Raw lists'!$B$2:$B$29,0))&" / ",""))&IF(L19="","",IFERROR(INDEX('Raw lists'!$B$2:$B$29,MATCH(L19,'Raw lists'!$B$2:$B$29,0))&" / ",""))&IF(M19="","",IFERROR(INDEX('Raw lists'!$B$2:$B$29,MATCH(M19,'Raw lists'!$B$2:$B$29,0))&" / ","")))-3)) | E19: =IF(LEN(IF(K19="","",IFERROR(INDEX('Raw lists'!$C$2:$C$23,MATCH(K19,'Raw lists'!$C$2:$C$23,0))&" / ",""))&IF(L19="","",IFERROR(INDEX('Raw lists'!$C$2:$C$23,MATCH(L19,'Raw lists'!$C$2:$C$23,0))&" / ",""))&IF(M19="","",IFERROR(INDEX('Raw lists'!$C$2:$C$23,MATCH(M19,'Raw lists'!$C$2:$C$23,0))&" / ","")))=0,"",LEFT(IF(K19="","",IFERROR(INDEX('Raw lists'!$C$2:$C$23,MATCH(K19,'Raw lists'!$C$2:$C$23,0))&" / ",""))&IF(L19="","",IFERROR(INDEX('Raw lists'!$C$2:$C$23,MATCH(L19,'Raw lists'!$C$2:$C$23,0))&" / ",""))&IF(M19="","",IFERROR(INDEX('Raw lists'!$C$2:$C$23,MATCH(M19,'Raw lists'!$C$2:$C$23,0))&" / ","")),LEN(IF(K19="","",IFERROR(INDEX('Raw lists'!$C$2:$C$23,MATCH(K19,'Raw lists'!$C$2:$C$23,0))&" / ",""))&IF(L19="","",IFERROR(INDEX('Raw lists'!$C$2:$C$23,MATCH(L19,'Raw lists'!$C$2:$C$23,0))&" / ",""))&IF(M19="","",IFERROR(INDEX('Raw lists'!$C$2:$C$23,MATCH(M19,'Raw lists'!$C$2:$C$23,0))&" / ","")))-3)) -> Subset Sum | F19: Core | G19: Is there a subset of the given positive integers that sums exactly to T? | H19: =COUNTIF(C19:E19,"?*") -> 2 | I19: =IF(H19=0,"None",IF(H19=3,"All three",IF(H19=1,"Only "&TRIM(IF(C19<>"","Gemini ","")&IF(D19<>"","RAKE ","")&IF(E19<>"","YAKE","")),SUBSTITUTE(TRIM(IF(C19<>"","Gemini ","")&IF(D19<>"","RAKE ","")&IF(E19<>"","YAKE",""))," "," + ")))) -> Gemini + YAKE | K19: Subset Sum
