Workbook

Sheet Claude vs tools
A1: # | B1: Claude's concept | C1: Gemini extracted | D1: RAKE extracted | E1: YAKE extracted | F1: Group | G1: Short description (from the PDF) | H1: Tools that found it | I1: Found by | K1: Accepted tool phrase 1 | L1: Accepted tool phrase 2 | M1: Accepted tool phrase 3 | N1: Accepted tool phrase 4 | O1: Accepted tool phrase 5 | P1: Accepted tool phrase 6 | R1: Legend
A2: 1 | B2: Polarization | C2: =IF(LEN(IF(K2="","",IFERROR(INDEX('Raw lists'!$A$2:$A$192,MATCH(K2,'Raw lists'!$A$2:$A$192,0))&" | ",""))&IF(L2="","",IFERROR(INDEX('Raw lists'!$A$2:$A$192,MATCH(L2,'Raw lists'!$A$2:$A$192,0))&" | ",""))&IF(M2="","",IFERROR(INDEX('Raw lists'!$A$2:$A$192,MATCH(M2,'Raw lists'!$A$2:$A$192,0))&" | ",""))&IF(N2="","",IFERROR(INDEX('Raw lists'!$A$2:$A$192,MATCH(N2,'Raw lists'!$A$2:$A$192,0))&" | ",""))&IF(O2="","",IFERROR(INDEX('Raw lists'!$A$2:$A$192,MATCH(O2,'Raw lists'!$A$2:$A$192,0))&" | ",""))&IF(P2="","",IFERROR(INDEX('Raw lists'!$A$2:$A$192,MATCH(P2,'Raw lists'!$A$2:$A$192,0))&" | ","")))=0,"",LEFT(IF(K2="","",IFERROR(INDEX('Raw lists'!$A$2:$A$192,MATCH(K2,'Raw lists'!$A$2:$A$192,0))&" | ",""))&IF(L2="","",IFERROR(INDEX('Raw lists'!$A$2:$A$192,MATCH(L2,'Raw lists'!$A$2:$A$192,0))&" | ",""))&IF(M2="","",IFERROR(INDEX('Raw lists'!$A$2:$A$192,MATCH(M2,'Raw lists'!$A$2:$A$192,0))&" | ",""))&IF(N2="","",IFERROR(INDEX('Raw lists'!$A$2:$A$192,MATCH(N2,'Raw lists'!$A$2:$A$192,0))&" | ",""))&IF(O2="","",IFERROR(INDEX('Raw lists'!$A$2:$A$192,MATCH(O2,'Raw lists'!$A$2:$A$192,0))&" | ",""))&IF(P2="","",IFERROR(INDEX('Raw lists'!$A$2:$A$192,MATCH(P2,'Raw lists'!$A$2:$A$192,0))&" | ","")),LEN(IF(K2="","",IFERROR(INDEX('Raw lists'!$A$2:$A$192,MATCH(K2,'Raw lists'!$A$2:$A$192,0))&" | ",""))&IF(L2="","",IFERROR(INDEX('Raw lists'!$A$2:$A$192,MATCH(L2,'Raw lists'!$A$2:$A$192,0))&" | ",""))&IF(M2="","",IFERROR(INDEX('Raw lists'!$A$2:$A$192,MATCH(M2,'Raw lists'!$A$2:$A$192,0))&" | ",""))&IF(N2="","",IFERROR(INDEX('Raw lists'!$A$2:$A$192,MATCH(N2,'Raw lists'!$A$2:$A$192,0))&" | ",""))&IF(O2="","",IFERROR(INDEX('Raw lists'!$A$2:$A$192,MATCH(O2,'Raw lists'!$A$2:$A$192,0))&" | ",""))&IF(P2="","",IFERROR(INDEX('Raw lists'!$A$2:$A$192,MATCH(P2,'Raw lists'!$A$2:$A$192,0))&" | ","")))-3)) -> Polarization | D2: =IF(LEN(IF(K2="","",IFERROR(INDEX('Raw lists'!$B$2:$B$627,MATCH(K2,'Raw lists'!$B$2:$B$627,0))&" | ",""))&IF(L2="","",IFERROR(INDEX('Raw lists'!$B$2:$B$627,MATCH(L2,'Raw lists'!$B$2:$B$627,0))&" | ",""))&IF(M2="","",IFERROR(INDEX('Raw lists'!$B$2:$B$627,MATCH(M2,'Raw lists'!$B$2:$B$627,0))&" | ",""))&IF(N2="","",IFERROR(INDEX('Raw lists'!$B$2:$B$627,MATCH(N2,'Raw lists'!$B$2:$B$627,0))&" | ",""))&IF(O2="","",IFERROR(INDEX('Raw lists'!$B$2:$B$627,MATCH(O2,'Raw lists'!$B$2:$B$627,0))&" | ",""))&IF(P2="","",IFERROR(INDEX('Raw lists'!$B$2:$B$627,MATCH(P2,'Raw lists'!$B$2:$B$627,0))&" | ","")))=0,"",LEFT(IF(K2="","",IFERROR(INDEX('Raw lists'!$B$2:$B$627,MATCH(K2,'Raw lists'!$B$2:$B$627,0))&" | ",""))&IF(L2="","",IFERROR(INDEX('Raw lists'!$B$2:$B$627,MATCH(L2,'Raw lists'!$B$2:$B$627,0))&" | ",""))&IF(M2="","",IFERROR(INDEX('Raw lists'!$B$2:$B$627,MATCH(M2,'Raw lists'!$B$2:$B$627,0))&" | ",""))&IF(N2="","",IFERROR(INDEX('Raw lists'!$B$2:$B$627,MATCH(N2,'Raw lists'!$B$2:$B$627,0))&" | ",""))&IF(O2="","",IFERROR(INDEX('Raw lists'!$B$2:$B$627,MATCH(O2,'Raw lists'!$B$2:$B$627,0))&" | ",""))&IF(P2="","",IFERROR(INDEX('Raw lists'!$B$2:$B$627,MATCH(P2,'Raw lists'!$B$2:$B$627,0))&" | ","")),LEN(IF(K2="","",IFERROR(INDEX('Raw lists'!$B$2:$B$627,MATCH(K2,'Raw lists'!$B$2:$B$627,0))&" | ",""))&IF(L2="","",IFERROR(INDEX('Raw lists'!$B$2:$B$627,MATCH(L2,'Raw lists'!$B$2:$B$627,0))&" | ",""))&IF(M2="","",IFERROR(INDEX('Raw lists'!$B$2:$B$627,MATCH(M2,'Raw lists'!$B$2:$B$627,0))&" | ",""))&IF(N2="","",IFERROR(INDEX('Raw lists'!$B$2:$B$627,MATCH(N2,'Raw lists'!$B$2:$B$627,0))&" | ",""))&IF(O2="","",IFERROR(INDEX('Raw lists'!$B$2:$B$627,MATCH(O2,'Raw lists'!$B$2:$B$627,0))&" | ",""))&IF(P2="","",IFERROR(INDEX('Raw lists'!$B$2:$B$627,MATCH(P2,'Raw lists'!$B$2:$B$627,0))&" | ","")))-3)) -> Polarization | E2: =IF(LEN(IF(K2="","",IFERROR(INDEX('Raw lists'!$C$2:$C$616,MATCH(K2,'Raw lists'!$C$2:$C$616,0))&" | ",""))&IF(L2="","",IFERROR(INDEX('Raw lists'!$C$2:$C$616,MATCH(L2,'Raw lists'!$C$2:$C$616,0))&" | ",""))&IF(M2="","",IFERROR(INDEX('Raw lists'!$C$2:$C$616,MATCH(M2,'Raw lists'!$C$2:$C$616,0))&" | ",""))&IF(N2="","",IFERROR(INDEX('Raw lists'!$C$2:$C$616,MATCH(N2,'Raw lists'!$C$2:$C$616,0))&" | ",""))&IF(O2="","",IFERROR(INDEX('Raw lists'!$C$2:$C$616,MATCH(O2,'Raw lists'!$C$2:$C$616,0))&" | ",""))&IF(P2="","",IFERROR(INDEX('Raw lists'!$C$2:$C$616,MATCH(P2,'Raw lists'!$C$2:$C$616,0))&" | ","")))=0,"",LEFT(IF(K2="","",IFERROR(INDEX('Raw lists'!$C$2:$C$616,MATCH(K2,'Raw lists'!$C$2:$C$616,0))&" | ",""))&IF(L2="","",IFERROR(INDEX('Raw lists'!$C$2:$C$616,MATCH(L2,'Raw lists'!$C$2:$C$616,0))&" | ",""))&IF(M2="","",IFERROR(INDEX('Raw lists'!$C$2:$C$616,MATCH(M2,'Raw lists'!$C$2:$C$616,0))&" | ",""))&IF(N2="","",IFERROR(INDEX('Raw lists'!$C$2:$C$616,MATCH(N2,'Raw lists'!$C$2:$C$616,0))&" | ",""))&IF(O2="","",IFERROR(INDEX('Raw lists'!$C$2:$C$616,MATCH(O2,'Raw lists'!$C$2:$C$616,0))&" | ",""))&IF(P2="","",IFERROR(INDEX('Raw lists'!$C$2:$C$616,MATCH(P2,'Raw lists'!$C$2:$C$616,0))&" | ","")),LEN(IF(K2="","",IFERROR(INDEX('Raw lists'!$C$2:$C$616,MATCH(K2,'Raw lists'!$C$2:$C$616,0))&" | ",""))&IF(L2="","",IFERROR(INDEX('Raw lists'!$C$2:$C$616,MATCH(L2,'Raw lists'!$C$2:$C$616,0))&" | ",""))&IF(M2="","",IFERROR(INDEX('Raw lists'!$C$2:$C$616,MATCH(M2,'Raw lists'!$C$2:$C$616,0))&" | ",""))&IF(N2="","",IFERROR(INDEX('Raw lists'!$C$2:$C$616,MATCH(N2,'Raw lists'!$C$2:$C$616,0))&" | ",""))&IF(O2="","",IFERROR(INDEX('Raw lists'!$C$2:$C$616,MATCH(O2,'Raw lists'!$C$2:$C$616,0))&" | ",""))&IF(P2="","",IFERROR(INDEX('Raw lists'!$C$2:$C$616,MATCH(P2,'Raw lists'!$C$2:$C$616,0))&" | ","")))-3)) -> Polarization | F2: Core | G2: Restricting the vibrations of a transverse wave to one plane. | H2: =COUNTIF(C2:E2,"?*") -> 3 | I2: =IF(H2=0,"None",IF(H2=3,"All three",IF(H2=1,"Only "&TRIM(IF(C2<>"","Gemini ","")&IF(D2<>"","RAKE ","")&IF(E2<>"","YAKE","")),SUBSTITUTE(TRIM(IF(C2<>"","Gemini ","")&IF(D2<>"","RAKE ","")&IF(E2<>"","YAKE",""))," "," + ")))) -> All three | K2: Polarization | R2: Found by all three tools
A3: 2 | B3: Transverse wave | C3: =IF(LEN(IF(K3="","",IFERROR(INDEX('Raw lists'!$A$2:$A$192,MATCH(K3,'Raw lists'!$A$2:$A$192,0))&" | ",""))&IF(L3="","",IFERROR(INDEX('Raw lists'!$A$2:$A$192,MATCH(L3,'Raw lists'!$A$2:$A$192,0))&" | ",""))&IF(M3="","",IFERROR(INDEX('Raw lists'!$A$2:$A$192,MATCH(M3,'Raw lists'!$A$2:$A$192,0))&" | ",""))&IF(N3="","",IFERROR(INDEX('Raw lists'!$A$2:$A$192,MATCH(N3,'Raw lists'!$A$2:$A$192,0))&" | ",""))&IF(O3="","",IFERROR(INDEX('Raw lists'!$A$2:$A$192,MATCH(O3,'Raw lists'!$A$2:$A$192,0))&" | ",""))&IF(P3="","",IFERROR(INDEX('Raw lists'!$A$2:$A$192,MATCH(P3,'Raw lists'!$A$2:$A$192,0))&" | ","")))=0,"",LEFT(IF(K3="","",IFERROR(INDEX('Raw lists'!$A$2:$A$192,MATCH(K3,'Raw lists'!$A$2:$A$192,0))&" | ",""))&IF(L3="","",IFERROR(INDEX('Raw lists'!$A$2:$A$192,MATCH(L3,'Raw lists'!$A$2:$A$192,0))&" | ",""))&IF(M3="","",IFERROR(INDEX('Raw lists'!$A$2:$A$192,MATCH(M3,'Raw lists'!$A$2:$A$192,0))&" | ",""))&IF(N3="","",IFERROR(INDEX('Raw lists'!$A$2:$A$192,MATCH(N3,'Raw lists'!$A$2:$A$192,0))&" | ",""))&IF(O3="","",IFERROR(INDEX('Raw lists'!$A$2:$A$192,MATCH(O3,'Raw lists'!$A$2:$A$192,0))&" | ",""))&IF(P3="","",IFERROR(INDEX('Raw lists'!$A$2:$A$192,MATCH(P3,'Raw lists'!$A$2:$A$192,0))&" | ","")),LEN(IF(K3="","",IFERROR(INDEX('Raw lists'!$A$2:$A$192,MATCH(K3,'Raw lists'!$A$2:$A$192,0))&" | ",""))&IF(L3="","",IFERROR(INDEX('Raw lists'!$A$2:$A$192,MATCH(L3,'Raw lists'!$A$2:$A$192,0))&" | ",""))&IF(M3="","",IFERROR(INDEX('Raw lists'!$A$2:$A$192,MATCH(M3,'Raw lists'!$A$2:$A$192,0))&" | ",""))&IF(N3="","",IFERROR(INDEX('Raw lists'!$A$2:$A$192,MATCH(N3,'Raw lists'!$A$2:$A$192,0))&" | ",""))&IF(O3="","",IFERROR(INDEX('Raw lists'!$A$2:$A$192,MATCH(O3,'Raw lists'!$A$2:$A$192,0))&" | ",""))&IF(P3="","",IFERROR(INDEX('Raw lists'!$A$2:$A$192,MATCH(P3,'Raw lists'!$A$2:$A$192,0))&" | ","")))-3)) | D3: =IF(LEN(IF(K3="","",IFERROR(INDEX('Raw lists'!$B$2:$B$627,MATCH(K3,'Raw lists'!$B$2:$B$627,0))&" | ",""))&IF(L3="","",IFERROR(INDEX('Raw lists'!$B$2:$B$627,MATCH(L3,'Raw lists'!$B$2:$B$627,0))&" | ",""))&IF(M3="","",IFERROR(INDEX('Raw lists'!$B$2:$B$627,MATCH(M3,'Raw lists'!$B$2:$B$627,0))&" | ",""))&IF(N3="","",IFERROR(INDEX('Raw lists'!$B$2:$B$627,MATCH(N3,'Raw lists'!$B$2:$B$627,0))&" | ",""))&IF(O3="","",IFERROR(INDEX('Raw lists'!$B$2:$B$627,MATCH(O3,'Raw lists'!$B$2:$B$627,0))&" | ",""))&IF(P3="","",IFERROR(INDEX('Raw lists'!$B$2:$B$627,MATCH(P3,'Raw lists'!$B$2:$B$627,0))&" | ","")))=0,"",LEFT(IF(K3="","",IFERROR(INDEX('Raw lists'!$B$2:$B$627,MATCH(K3,'Raw lists'!$B$2:$B$627,0))&" | ",""))&IF(L3="","",IFERROR(INDEX('Raw lists'!$B$2:$B$627,MATCH(L3,'Raw lists'!$B$2:$B$627,0))&" | ",""))&IF(M3="","",IFERROR(INDEX('Raw lists'!$B$2:$B$627,MATCH(M3,'Raw lists'!$B$2:$B$627,0))&" | ",""))&IF(N3="","",IFERROR(INDEX('Raw lists'!$B$2:$B$627,MATCH(N3,'Raw lists'!$B$2:$B$627,0))&" | ",""))&IF(O3="","",IFERROR(INDEX('Raw lists'!$B$2:$B$627,MATCH(O3,'Raw lists'!$B$2:$B$627,0))&" | ",""))&IF(P3="","",IFERROR(INDEX('Raw lists'!$B$2:$B$627,MATCH(P3,'Raw lists'!$B$2:$B$627,0))&" | ","")),LEN(IF(K3="","",IFERROR(INDEX('Raw lists'!$B$2:$B$627,MATCH(K3,'Raw lists'!$B$2:$B$627,0))&" | ",""))&IF(L3="","",IFERROR(INDEX('Raw lists'!$B$2:$B$627,MATCH(L3,'Raw lists'!$B$2:$B$627,0))&" | ",""))&IF(M3="","",IFERROR(INDEX('Raw lists'!$B$2:$B$627,MATCH(M3,'Raw lists'!$B$2:$B$627,0))&" | ",""))&IF(N3="","",IFERROR(INDEX('Raw lists'!$B$2:$B$627,MATCH(N3,'Raw lists'!$B$2:$B$627,0))&" | ",""))&IF(O3="","",IFERROR(INDEX('Raw lists'!$B$2:$B$627,MATCH(O3,'Raw lists'!$B$2:$B$627,0))&" | ",""))&IF(P3="","",IFERROR(INDEX('Raw lists'!$B$2:$B$627,MATCH(P3,'Raw lists'!$B$2:$B$627,0))&" | ","")))-3)) -> Transverse Wave | E3: =IF(LEN(IF(K3="","",IFERROR(INDEX('Raw lists'!$C$2:$C$616,MATCH(K3,'Raw lists'!$C$2:$C$616,0))&" | ",""))&IF(L3="","",IFERROR(INDEX('Raw lists'!$C$2:$C$616,MATCH(L3,'Raw lists'!$C$2:$C$616,0))&" | ",""))&IF(M3="","",IFERROR(INDEX('Raw lists'!$C$2:$C$616,MATCH(M3,'Raw lists'!$C$2:$C$616,0))&" | ",""))&IF(N3="","",IFERROR(INDEX('Raw lists'!$C$2:$C$616,MATCH(N3,'Raw lists'!$C$2:$C$616,0))&" | ",""))&IF(O3="","",IFERROR(INDEX('Raw lists'!$C$2:$C$616,MATCH(O3,'Raw lists'!$C$2:$C$616,0))&" | ",""))&IF(P3="","",IFERROR(INDEX('Raw lists'!$C$2:$C$616,MATCH(P3,'Raw lists'!$C$2:$C$616,0))&" | ","")))=0,"",LEFT(IF(K3="","",IFERROR(INDEX('Raw lists'!$C$2:$C$616,MATCH(K3,'Raw lists'!$C$2:$C$616,0))&" | ",""))&IF(L3="","",IFERROR(INDEX('Raw lists'!$C$2:$C$616,MATCH(L3,'Raw lists'!$C$2:$C$616,0))&" | ",""))&IF(M3="","",IFERROR(INDEX('Raw lists'!$C$2:$C$616,MATCH(M3,'Raw lists'!$C$2:$C$616,0))&" | ",""))&IF(N3="","",IFERROR(INDEX('Raw lists'!$C$2:$C$616,MATCH(N3,'Raw lists'!$C$2:$C$616,0))&" | ",""))&IF(O3="","",IFERROR(INDEX('Raw lists'!$C$2:$C$616,MATCH(O3,'Raw lists'!$C$2:$C$616,0))&" | ",""))&IF(P3="","",IFERROR(INDEX('Raw lists'!$C$2:$C$616,MATCH(P3,'Raw lists'!$C$2:$C$616,0))&" | ","")),LEN(IF(K3="","",IFERROR(INDEX('Raw lists'!$C$2:$C$616,MATCH(K3,'Raw lists'!$C$2:$C$616,0))&" | ",""))&IF(L3="","",IFERROR(INDEX('Raw lists'!$C$2:$C$616,MATCH(L3,'Raw lists'!$C$2:$C$616,0))&" | ",""))&IF(M3="","",IFERROR(INDEX('Raw lists'!$C$2:$C$616,MATCH(M3,'Raw lists'!$C$2:$C$616,0))&" | ",""))&IF(N3="","",IFERROR(INDEX('Raw lists'!$C$2:$C$616,MATCH(N3,'Raw lists'!$C$2:$C$616,0))&" | ",""))&IF(O3="","",IFERROR(INDEX('Raw lists'!$C$2:$C$616,MATCH(O3,'Raw lists'!$C$2:$C$616,0))&" | ",""))&IF(P3="","",IFERROR(INDEX('Raw lists'!$C$2:$C$616,MATCH(P3,'Raw lists'!$C$2:$C$616,0))&" | ","")))-3)) -> Transverse Wave | F3: Core | G3: Wave whose vibrations are perpendicular to its direction of propagation. | H3: =COUNTIF(C3:E3,"?*") -> 2 | I3: =IF(H3=0,"None",IF(H3=3,"All three",IF(H3=1,"Only "&TRIM(IF(C3<>"","Gemini ","")&IF(D3<>"","RAKE ","")&IF(E3<>"","YAKE","")),SUBSTITUTE(TRIM(IF(C3<>"","Gemini ","")&IF(D3<>"","RAKE ","")&IF(E3<>"","YAKE",""))," "," + ")))) -> RAKE + YAKE | K3: Transverse Wave | R3: Found by two tools
A4: 3 | B4: Longitudinal wave | C4: =IF(LEN(IF(K4="","",IFERROR(INDEX('Raw lists'!$A$2:$A$192,MATCH(K4,'Raw lists'!$A$2:$A$192,0))&" | ",""))&IF(L4="","",IFERROR(INDEX('Raw lists'!$A$2:$A$192,MATCH(L4,'Raw lists'!$A$2:$A$192,0))&" | ",""))&IF(M4="","",IFERROR(INDEX('Raw lists'!$A$2:$A$192,MATCH(M4,'Raw lists'!$A$2:$A$192,0))&" | ",""))&IF(N4="","",IFERROR(INDEX('Raw lists'!$A$2:$A$192,MATCH(N4,'Raw lists'!$A$2:$A$192,0))&" | ",""))&IF(O4="","",IFERROR(INDEX('Raw lists'!$A$2:$A$192,MATCH(O4,'Raw lists'!$A$2:$A$192,0))&" | ",""))&IF(P4="","",IFERROR(INDEX('Raw lists'!$A$2:$A$192,MATCH(P4,'Raw lists'!$A$2:$A$192,0))&" | ","")))=0,"",LEFT(IF(K4="","",IFERROR(INDEX('Raw lists'!$A$2:$A$192,MATCH(K4,'Raw lists'!$A$2:$A$192,0))&" | ",""))&IF(L4="","",IFERROR(INDEX('Raw lists'!$A$2:$A$192,MATCH(L4,'Raw lists'!$A$2:$A$192,0))&" | ",""))&IF(M4="","",IFERROR(INDEX('Raw lists'!$A$2:$A$192,MATCH(M4,'Raw lists'!$A$2:$A$192,0))&" | ",""))&IF(N4="","",IFERROR(INDEX('Raw lists'!$A$2:$A$192,MATCH(N4,'Raw lists'!$A$2:$A$192,0))&" | ",""))&IF(O4="","",IFERROR(INDEX('Raw lists'!$A$2:$A$192,MATCH(O4,'Raw lists'!$A$2:$A$192,0))&" | ",""))&IF(P4="","",IFERROR(INDEX('Raw lists'!$A$2:$A$192,MATCH(P4,'Raw lists'!$A$2:$A$192,0))&" | ","")),LEN(IF(K4="","",IFERROR(INDEX('Raw lists'!$A$2:$A$192,MATCH(K4,'Raw lists'!$A$2:$A$192,0))&" | ",""))&IF(L4="","",IFERROR(INDEX('Raw lists'!$A$2:$A$192,MATCH(L4,'Raw lists'!$A$2:$A$192,0))&" | ",""))&IF(M4="","",IFERROR(INDEX('Raw lists'!$A$2:$A$192,MATCH(M4,'Raw lists'!$A$2:$A$192,0))&" | ",""))&IF(N4="","",IFERROR(INDEX('Raw lists'!$A$2:$A$192,MATCH(N4,'Raw lists'!$A$2:$A$192,0))&" | ",""))&IF(O4="","",IFERROR(INDEX('Raw lists'!$A$2:$A$192,MATCH(O4,'Raw lists'!$A$2:$A$192,0))&" | ",""))&IF(P4="","",IFERROR(INDEX('Raw lists'!$A$2:$A$192,MATCH(P4,'Raw lists'!$A$2:$A$192,0))&" | ","")))-3)) | D4: =IF(LEN(IF(K4="","",IFERROR(INDEX('Raw lists'!$B$2:$B$627,MATCH(K4,'Raw lists'!$B$2:$B$627,0))&" | ",""))&IF(L4="","",IFERROR(INDEX('Raw lists'!$B$2:$B$627,MATCH(L4,'Raw lists'!$B$2:$B$627,0))&" | ",""))&IF(M4="","",IFERROR(INDEX('Raw lists'!$B$2:$B$627,MATCH(M4,'Raw lists'!$B$2:$B$627,0))&" | ",""))&IF(N4="","",IFERROR(INDEX('Raw lists'!$B$2:$B$627,MATCH(N4,'Raw lists'!$B$2:$B$627,0))&" | ",""))&IF(O4="","",IFERROR(INDEX('Raw lists'!$B$2:$B$627,MATCH(O4,'Raw lists'!$B$2:$B$627,0))&" | ",""))&IF(P4="","",IFERROR(INDEX('Raw lists'!$B$2:$B$627,MATCH(P4,'Raw lists'!$B$2:$B$627,0))&" | ","")))=0,"",LEFT(IF(K4="","",IFERROR(INDEX('Raw lists'!$B$2:$B$627,MATCH(K4,'Raw lists'!$B$2:$B$627,0))&" | ",""))&IF(L4="","",IFERROR(INDEX('Raw lists'!$B$2:$B$627,MATCH(L4,'Raw lists'!$B$2:$B$627,0))&" | ",""))&IF(M4="","",IFERROR(INDEX('Raw lists'!$B$2:$B$627,MATCH(M4,'Raw lists'!$B$2:$B$627,0))&" | ",""))&IF(N4="","",IFERROR(INDEX('Raw lists'!$B$2:$B$627,MATCH(N4,'Raw lists'!$B$2:$B$627,0))&" | ",""))&IF(O4="","",IFERROR(INDEX('Raw lists'!$B$2:$B$627,MATCH(O4,'Raw lists'!$B$2:$B$627,0))&" | ",""))&IF(P4="","",IFERROR(INDEX('Raw lists'!$B$2:$B$627,MATCH(P4,'Raw lists'!$B$2:$B$627,0))&" | ","")),LEN(IF(K4="","",IFERROR(INDEX('Raw lists'!$B$2:$B$627,MATCH(K4,'Raw lists'!$B$2:$B$627,0))&" | ",""))&IF(L4="","",IFERROR(INDEX('Raw lists'!$B$2:$B$627,MATCH(L4,'Raw lists'!$B$2:$B$627,0))&" | ",""))&IF(M4="","",IFERROR(INDEX('Raw lists'!$B$2:$B$627,MATCH(M4,'Raw lists'!$B$2:$B$627,0))&" | ",""))&IF(N4="","",IFERROR(INDEX('Raw lists'!$B$2:$B$627,MATCH(N4,'Raw lists'!$B$2:$B$627,0))&" | ",""))&IF(O4="","",IFERROR(INDEX('Raw lists'!$B$2:$B$627,MATCH(O4,'Raw lists'!$B$2:$B$627,0))&" | ",""))&IF(P4="","",IFERROR(INDEX('Raw lists'!$B$2:$B$627,MATCH(P4,'Raw lists'!$B$2:$B$627,0))&" | ","")))-3)) -> Longitudinal Waves | E4: =IF(LEN(IF(K4="","",IFERROR(INDEX('Raw lists'!$C$2:$C$616,MATCH(K4,'Raw lists'!$C$2:$C$616,0))&" | ",""))&IF(L4="","",IFERROR(INDEX('Raw lists'!$C$2:$C$616,MATCH(L4,'Raw lists'!$C$2:$C$616,0))&" | ",""))&IF(M4="","",IFERROR(INDEX('Raw lists'!$C$2:$C$616,MATCH(M4,'Raw lists'!$C$2:$C$616,0))&" | ",""))&IF(N4="","",IFERROR(INDEX('Raw lists'!$C$2:$C$616,MATCH(N4,'Raw lists'!$C$2:$C$616,0))&" | ",""))&IF(O4="","",IFERROR(INDEX('Raw lists'!$C$2:$C$616,MATCH(O4,'Raw lists'!$C$2:$C$616,0))&" | ",""))&IF(P4="","",IFERROR(INDEX('Raw lists'!$C$2:$C$616,MATCH(P4,'Raw lists'!$C$2:$C$616,0))&" | ","")))=0,"",LEFT(IF(K4="","",IFERROR(INDEX('Raw lists'!$C$2:$C$616,MATCH(K4,'Raw lists'!$C$2:$C$616,0))&" | ",""))&IF(L4="","",IFERROR(INDEX('Raw lists'!$C$2:$C$616,MATCH(L4,'Raw lists'!$C$2:$C$616,0))&" | ",""))&IF(M4="","",IFERROR(INDEX('Raw lists'!$C$2:$C$616,MATCH(M4,'Raw lists'!$C$2:$C$616,0))&" | ",""))&IF(N4="","",IFERROR(INDEX('Raw lists'!$C$2:$C$616,MATCH(N4,'Raw lists'!$C$2:$C$616,0))&" | ",""))&IF(O4="","",IFERROR(INDEX('Raw lists'!$C$2:$C$616,MATCH(O4,'Raw lists'!$C$2:$C$616,0))&" | ",""))&IF(P4="","",IFERROR(INDEX('Raw lists'!$C$2:$C$616,MATCH(P4,'Raw lists'!$C$2:$C$616,0))&" | ","")),LEN(IF(K4="","",IFERROR(INDEX('Raw lists'!$C$2:$C$616,MATCH(K4,'Raw lists'!$C$2:$C$616,0))&" | ",""))&IF(L4="","",IFERROR(INDEX('Raw lists'!$C$2:$C$616,MATCH(L4,'Raw lists'!$C$2:$C$616,0))&" | ",""))&IF(M4="","",IFERROR(INDEX('Raw lists'!$C$2:$C$616,MATCH(M4,'Raw lists'!$C$2:$C$616,0))&" | ",""))&IF(N4="","",IFERROR(INDEX('Raw lists'!$C$2:$C$616,MATCH(N4,'Raw lists'!$C$2:$C$616,0))&" | ",""))&IF(O4="","",IFERROR(INDEX('Raw lists'!$C$2:$C$616,MATCH(O4,'Raw lists'!$C$2:$C$616,0))&" | ",""))&IF(P4="","",IFERROR(INDEX('Raw lists'!$C$2:$C$616,MATCH(P4,'Raw lists'!$C$2:$C$616,0))&" | ","")))-3)) | F4: Core | G4: Wave that does not show polarization. | H4: =COUNTIF(C4:E4,"?*") -> 1 | I4: =IF(H4=0,"None",IF(H4=3,"All three",IF(H4=1,"Only "&TRIM(IF(C4<>"","Gemini ","")&IF(D4<>"","RAKE ","")&IF(E4<>"","YAKE","")),SUBSTITUTE(TRIM(IF(C4<>"","Gemini ","")&IF(D4<>"","RAKE ","")&IF(E4<>"","YAKE",""))," "," + ")))) -> Only RAKE | K4: Longitudinal Waves | L4: Longitudinal Wave | R4: Found by none of the tools
A5: 4 | B5: Polarized light (plane polarized) | C5: =IF(LEN(IF(K5="","",IFERROR(INDEX('Raw lists'!$A$2:$A$192,MATCH(K5,'Raw lists'!$A$2:$A$192,0))&" | ",""))&IF(L5="","",IFERROR(INDEX('Raw lists'!$A$2:$A$192,MATCH(L5,'Raw lists'!$A$2:$A$192,0))&" | ",""))&IF(M5="","",IFERROR(INDEX('Raw lists'!$A$2:$A$192,MATCH(M5,'Raw lists'!$A$2:$A$192,0))&" | ",""))&IF(N5="","",IFERROR(INDEX('Raw lists'!$A$2:$A$192,MATCH(N5,'Raw lists'!$A$2:$A$192,0))&" | ",""))&IF(O5="","",IFERROR(INDEX('Raw lists'!$A$2:$A$192,MATCH(O5,'Raw lists'!$A$2:$A$192,0))&" | ",""))&IF(P5="","",IFERROR(INDEX('Raw lists'!$A$2:$A$192,MATCH(P5,'Raw lists'!$A$2:$A$192,0))&" | ","")))=0,"",LEFT(IF(K5="","",IFERROR(INDEX('Raw lists'!$A$2:$A$192,MATCH(K5,'Raw lists'!$A$2:$A$192,0))&" | ",""))&IF(L5="","",IFERROR(INDEX('Raw lists'!$A$2:$A$192,MATCH(L5,'Raw lists'!$A$2:$A$192,0))&" | ",""))&IF(M5="","",IFERROR(INDEX('Raw lists'!$A$2:$A$192,MATCH(M5,'Raw lists'!$A$2:$A$192,0))&" | ",""))&IF(N5="","",IFERROR(INDEX('Raw lists'!$A$2:$A$192,MATCH(N5,'Raw lists'!$A$2:$A$192,0))&" | ",""))&IF(O5="","",IFERROR(INDEX('Raw lists'!$A$2:$A$192,MATCH(O5,'Raw lists'!$A$2:$A$192,0))&" | ",""))&IF(P5="","",IFERROR(INDEX('Raw lists'!$A$2:$A$192,MATCH(P5,'Raw lists'!$A$2:$A$192,0))&" | ","")),LEN(IF(K5="","",IFERROR(INDEX('Raw lists'!$A$2:$A$192,MATCH(K5,'Raw lists'!$A$2:$A$192,0))&" | ",""))&IF(L5="","",IFERROR(INDEX('Raw lists'!$A$2:$A$192,MATCH(L5,'Raw lists'!$A$2:$A$192,0))&" | ",""))&IF(M5="","",IFERROR(INDEX('Raw lists'!$A$2:$A$192,MATCH(M5,'Raw lists'!$A$2:$A$192,0))&" | ",""))&IF(N5="","",IFERROR(INDEX('Raw lists'!$A$2:$A$192,MATCH(N5,'Raw lists'!$A$2:$A$192,0))&" | ",""))&IF(O5="","",IFERROR(INDEX('Raw lists'!$A$2:$A$192,MATCH(O5,'Raw lists'!$A$2:$A$192,0))&" | ",""))&IF(P5="","",IFERROR(INDEX('Raw lists'!$A$2:$A$192,MATCH(P5,'Raw lists'!$A$2:$A$192,0))&" | ","")))-3)) -> Polarized Light | Plane Polarized Light | Plane-polarized Wave | D5: =IF(LEN(IF(K5="","",IFERROR(INDEX('Raw lists'!$B$2:$B$627,MATCH(K5,'Raw lists'!$B$2:$B$627,0))&" | ",""))&IF(L5="","",IFERROR(INDEX('Raw lists'!$B$2:$B$627,MATCH(L5,'Raw lists'!$B$2:$B$627,0))&" | ",""))&IF(M5="","",IFERROR(INDEX('Raw lists'!$B$2:$B$627,MATCH(M5,'Raw lists'!$B$2:$B$627,0))&" | ",""))&IF(N5="","",IFERROR(INDEX('Raw lists'!$B$2:$B$627,MATCH(N5,'Raw lists'!$B$2:$B$627,0))&" | ",""))&IF(O5="","",IFERROR(INDEX('Raw lists'!$B$2:$B$627,MATCH(O5,'Raw lists'!$B$2:$B$627,0))&" | ",""))&IF(P5="","",IFERROR(INDEX('Raw lists'!$B$2:$B$627,MATCH(P5,'Raw lists'!$B$2:$B$627,0))&" | ","")))=0,"",LEFT(IF(K5="","",IFERROR(INDEX('Raw lists'!$B$2:$B$627,MATCH(K5,'Raw lists'!$B$2:$B$627,0))&" | ",""))&IF(L5="","",IFERROR(INDEX('Raw lists'!$B$2:$B$627,MATCH(L5,'Raw lists'!$B$2:$B$627,0))&" | ",""))&IF(M5="","",IFERROR(INDEX('Raw lists'!$B$2:$B$627,MATCH(M5,'Raw lists'!$B$2:$B$627,0))&" | ",""))&IF(N5="","",IFERROR(INDEX('Raw lists'!$B$2:$B$627,MATCH(N5,'Raw lists'!$B$2:$B$627,0))&" | ",""))&IF(O5="","",IFERROR(INDEX('Raw lists'!$B$2:$B$627,MATCH(O5,'Raw lists'!$B$2:$B$627,0))&" | ",""))&IF(P5="","",IFERROR(INDEX('Raw lists'!$B$2:$B$627,MATCH(P5,'Raw lists'!$B$2:$B$627,0))&" | ","")),LEN(IF(K5="","",IFERROR(INDEX('Raw lists'!$B$2:$B$627,MATCH(K5,'Raw lists'!$B$2:$B$627,0))&" | ",""))&IF(L5="","",IFERROR(INDEX('Raw lists'!$B$2:$B$627,MATCH(L5,'Raw lists'!$B$2:$B$627,0))&" | ",""))&IF(M5="","",IFERROR(INDEX('Raw lists'!$B$2:$B$627,MATCH(M5,'Raw lists'!$B$2:$B$627,0))&" | ",""))&IF(N5="","",IFERROR(INDEX('Raw lists'!$B$2:$B$627,MATCH(N5,'Raw lists'!$B$2:$B$627,0))&" | ",""))&IF(O5="","",IFERROR(INDEX('Raw lists'!$B$2:$B$627,MATCH(O5,'Raw lists'!$B$2:$B$627,0))&" | ",""))&IF(P5="","",IFERROR(INDEX('Raw lists'!$B$2:$B$627,MATCH(P5,'Raw lists'!$B$2:$B$627,0))&" | ","")))-3)) -> Polarized Light | Plane Polarized Light | Plane Polarized | Linearly Polarized | E5: =IF(LEN(IF(K5="","",IFERROR(INDEX('Raw lists'!$C$2:$C$616,MATCH(K5,'Raw lists'!$C$2:$C$616,0))&" | ",""))&IF(L5="","",IFERROR(INDEX('Raw lists'!$C$2:$C$616,MATCH(L5,'Raw lists'!$C$2:$C$616,0))&" | ",""))&IF(M5="","",IFERROR(INDEX('Raw lists'!$C$2:$C$616,MATCH(M5,'Raw lists'!$C$2:$C$616,0))&" | ",""))&IF(N5="","",IFERROR(INDEX('Raw lists'!$C$2:$C$616,MATCH(N5,'Raw lists'!$C$2:$C$616,0))&" | ",""))&IF(O5="","",IFERROR(INDEX('Raw lists'!$C$2:$C$616,MATCH(O5,'Raw lists'!$C$2:$C$616,0))&" | ",""))&IF(P5="","",IFERROR(INDEX('Raw lists'!$C$2:$C$616,MATCH(P5,'Raw lists'!$C$2:$C$616,0))&" | ","")))=0,"",LEFT(IF(K5="","",IFERROR(INDEX('Raw lists'!$C$2:$C$616,MATCH(K5,'Raw lists'!$C$2:$C$616,0))&" | ",""))&IF(L5="","",IFERROR(INDEX('Raw lists'!$C$2:$C$616,MATCH(L5,'Raw lists'!$C$2:$C$616,0))&" | ",""))&IF(M5="","",IFERROR(INDEX('Raw lists'!$C$2:$C$616,MATCH(M5,'Raw lists'!$C$2:$C$616,0))&" | ",""))&IF(N5="","",IFERROR(INDEX('Raw lists'!$C$2:$C$616,MATCH(N5,'Raw lists'!$C$2:$C$616,0))&" | ",""))&IF(O5="","",IFERROR(INDEX('Raw lists'!$C$2:$C$616,MATCH(O5,'Raw lists'!$C$2:$C$616,0))&" | ",""))&IF(P5="","",IFERROR(INDEX('Raw lists'!$C$2:$C$616,MATCH(P5,'Raw lists'!$C$2:$C$616,0))&" | ","")),LEN(IF(K5="","",IFERROR(INDEX('Raw lists'!$C$2:$C$616,MATCH(K5,'Raw lists'!$C$2:$C$616,0))&" | ",""))&IF(L5="","",IFERROR(INDEX('Raw lists'!$C$2:$C$616,MATCH(L5,'Raw lists'!$C$2:$C$616,0))&" | ",""))&IF(M5="","",IFERROR(INDEX('Raw lists'!$C$2:$C$616,MATCH(M5,'Raw lists'!$C$2:$C$616,0))&" | ",""))&IF(N5="","",IFERROR(INDEX('Raw lists'!$C$2:$C$616,MATCH(N5,'Raw lists'!$C$2:$C$616,0))&" | ",""))&IF(O5="","",IFERROR(INDEX('Raw lists'!$C$2:$C$616,MATCH(O5,'Raw lists'!$C$2:$C$616,0))&" | ",""))&IF(P5="","",IFERROR(INDEX('Raw lists'!$C$2:$C$616,MATCH(P5,'Raw lists'!$C$2:$C$616,0))&" | ","")))-3)) -> Polarized Light | Plane Polarized Light | Plane Polarized | F5: Core | G5: Light vibrating along only one plane perpendicular to its direction of travel; also called linearly polarized. | H5: =COUNTIF(C5:E5,"?*") -> 3 | I5: =IF(H5=0,"None",IF(H5=3,"All three",IF(H5=1,"Only "&TRIM(IF(C5<>"","Gemini ","")&IF(D5<>"","RAKE ","")&IF(E5<>"","YAKE","")),SUBSTITUTE(TRIM(IF(C5<>"","Gemini ","")&IF(D5<>"","RAKE ","")&IF(E5<>"","YAKE",""))," "," + ")))) -> All three | K5: Polarized Light | L5: Plane Polarized Light | M5: Plane Polarized | N5: Plane-polarized Wave | O5: Plane Polarized Wave | P5: Linearly Polarized | R5: Extracted by tools, not in Claude's list
A6: 5 | B6: Unpolarized light | C6: =IF(LEN(IF(K6="","",IFERROR(INDEX('Raw lists'!$A$2:$A$192,MATCH(K6,'Raw lists'!$A$2:$A$192,0))&" | ",""))&IF(L6="","",IFERROR(INDEX('Raw lists'!$A$2:$A$192,MATCH(L6,'Raw lists'!$A$2:$A$192,0))&" | ",""))&IF(M6="","",IFERROR(INDEX('Raw lists'!$A$2:$A$192,MATCH(M6,'Raw lists'!$A$2:$A$192,0))&" | ",""))&IF(N6="","",IFERROR(INDEX('Raw lists'!$A$2:$A$192,MATCH(N6,'Raw lists'!$A$2:$A$192,0))&" | ",""))&IF(O6="","",IFERROR(INDEX('Raw lists'!$A$2:$A$192,MATCH(O6,'Raw lists'!$A$2:$A$192,0))&" | ",""))&IF(P6="","",IFERROR(INDEX('Raw lists'!$A$2:$A$192,MATCH(P6,'Raw lists'!$A$2:$A$192,0))&" | ","")))=0,"",LEFT(IF(K6="","",IFERROR(INDEX('Raw lists'!$A$2:$A$192,MATCH(K6,'Raw lists'!$A$2:$A$192,0))&" | ",""))&IF(L6="","",IFERROR(INDEX('Raw lists'!$A$2:$A$192,MATCH(L6,'Raw lists'!$A$2:$A$192,0))&" | ",""))&IF(M6="","",IFERROR(INDEX('Raw lists'!$A$2:$A$192,MATCH(M6,'Raw lists'!$A$2:$A$192,0))&" | ",""))&IF(N6="","",IFERROR(INDEX('Raw lists'!$A$2:$A$192,MATCH(N6,'Raw lists'!$A$2:$A$192,0))&" | ",""))&IF(O6="","",IFERROR(INDEX('Raw lists'!$A$2:$A$192,MATCH(O6,'Raw lists'!$A$2:$A$192,0))&" | ",""))&IF(P6="","",IFERROR(INDEX('Raw lists'!$A$2:$A$192,MATCH(P6,'Raw lists'!$A$2:$A$192,0))&" | ","")),LEN(IF(K6="","",IFERROR(INDEX('Raw lists'!$A$2:$A$192,MATCH(K6,'Raw lists'!$A$2:$A$192,0))&" | ",""))&IF(L6="","",IFERROR(INDEX('Raw lists'!$A$2:$A$192,MATCH(L6,'Raw lists'!$A$2:$A$192,0))&" | ",""))&IF(M6="","",IFERROR(INDEX('Raw lists'!$A$2:$A$192,MATCH(M6,'Raw lists'!$A$2:$A$192,0))&" | ",""))&IF(N6="","",IFERROR(INDEX('Raw lists'!$A$2:$A$192,MATCH(N6,'Raw lists'!$A$2:$A$192,0))&" | ",""))&IF(O6="","",IFERROR(INDEX('Raw lists'!$A$2:$A$192,MATCH(O6,'Raw lists'!$A$2:$A$192,0))&" | ",""))&IF(P6="","",IFERROR(INDEX('Raw lists'!$A$2:$A$192,MATCH(P6,'Raw lists'!$A$2:$A$192,0))&" | ","")))-3)) -> Unpolarized Light | D6: =IF(LEN(IF(K6="","",IFERROR(INDEX('Raw lists'!$B$2:$B$627,MATCH(K6,'Raw lists'!$B$2:$B$627,0))&" | ",""))&IF(L6="","",IFERROR(INDEX('Raw lists'!$B$2:$B$627,MATCH(L6,'Raw lists'!$B$2:$B$627,0))&" | ",""))&IF(M6="","",IFERROR(INDEX('Raw lists'!$B$2:$B$627,MATCH(M6,'Raw lists'!$B$2:$B$627,0))&" | ",""))&IF(N6="","",IFERROR(INDEX('Raw lists'!$B$2:$B$627,MATCH(N6,'Raw lists'!$B$2:$B$627,0))&" | ",""))&IF(O6="","",IFERROR(INDEX('Raw lists'!$B$2:$B$627,MATCH(O6,'Raw lists'!$B$2:$B$627,0))&" | ",""))&IF(P6="","",IFERROR(INDEX('Raw lists'!$B$2:$B$627,MATCH(P6,'Raw lists'!$B$2:$B$627,0))&" | ","")))=0,"",LEFT(IF(K6="","",IFERROR(INDEX('Raw lists'!$B$2:$B$627,MATCH(K6,'Raw lists'!$B$2:$B$627,0))&" | ",""))&IF(L6="","",IFERROR(INDEX('Raw lists'!$B$2:$B$627,MATCH(L6,'Raw lists'!$B$2:$B$627,0))&" | ",""))&IF(M6="","",IFERROR(INDEX('Raw lists'!$B$2:$B$627,MATCH(M6,'Raw lists'!$B$2:$B$627,0))&" | ",""))&IF(N6="","",IFERROR(INDEX('Raw lists'!$B$2:$B$627,MATCH(N6,'Raw lists'!$B$2:$B$627,0))&" | ",""))&IF(O6="","",IFERROR(INDEX('Raw lists'!$B$2:$B$627,MATCH(O6,'Raw lists'!$B$2:$B$627,0))&" | ",""))&IF(P6="","",IFERROR(INDEX('Raw lists'!$B$2:$B$627,MATCH(P6,'Raw lists'!$B$2:$B$627,0))&" | ","")),LEN(IF(K6="","",IFERROR(INDEX('Raw lists'!$B$2:$B$627,MATCH(K6,'Raw lists'!$B$2:$B$627,0))&" | ",""))&IF(L6="","",IFERROR(INDEX('Raw lists'!$B$2:$B$627,MATCH(L6,'Raw lists'!$B$2:$B$627,0))&" | ",""))&IF(M6="","",IFERROR(INDEX('Raw lists'!$B$2:$B$627,MATCH(M6,'Raw lists'!$B$2:$B$627,0))&" | ",""))&IF(N6="","",IFERROR(INDEX('Raw lists'!$B$2:$B$627,MATCH(N6,'Raw lists'!$B$2:$B$627,0))&" | ",""))&IF(O6="","",IFERROR(INDEX('Raw lists'!$B$2:$B$627,MATCH(O6,'Raw lists'!$B$2:$B$627,0))&" | ",""))&IF(P6="","",IFERROR(INDEX('Raw lists'!$B$2:$B$627,MATCH(P6,'Raw lists'!$B$2:$B$627,0))&" | ","")))-3)) -> Unpolarized Light | E6: =IF(LEN(IF(K6="","",IFERROR(INDEX('Raw lists'!$C$2:$C$616,MATCH(K6,'Raw lists'!$C$2:$C$616,0))&" | ",""))&IF(L6="","",IFERROR(INDEX('Raw lists'!$C$2:$C$616,MATCH(L6,'Raw lists'!$C$2:$C$616,0))&" | ",""))&IF(M6="","",IFERROR(INDEX('Raw lists'!$C$2:$C$616,MATCH(M6,'Raw lists'!$C$2:$C$616,0))&" | ",""))&IF(N6="","",IFERROR(INDEX('Raw lists'!$C$2:$C$616,MATCH(N6,'Raw lists'!$C$2:$C$616,0))&" | ",""))&IF(O6="","",IFERROR(INDEX('Raw lists'!$C$2:$C$616,MATCH(O6,'Raw lists'!$C$2:$C$616,0))&" | ",""))&IF(P6="","",IFERROR(INDEX('Raw lists'!$C$2:$C$616,MATCH(P6,'Raw lists'!$C$2:$C$616,0))&" | ","")))=0,"",LEFT(IF(K6="","",IFERROR(INDEX('Raw lists'!$C$2:$C$616,MATCH(K6,'Raw lists'!$C$2:$C$616,0))&" | ",""))&IF(L6="","",IFERROR(INDEX('Raw lists'!$C$2:$C$616,MATCH(L6,'Raw lists'!$C$2:$C$616,0))&" | ",""))&IF(M6="","",IFERROR(INDEX('Raw lists'!$C$2:$C$616,MATCH(M6,'Raw lists'!$C$2:$C$616,0))&" | ",""))&IF(N6="","",IFERROR(INDEX('Raw lists'!$C$2:$C$616,MATCH(N6,'Raw lists'!$C$2:$C$616,0))&" | ",""))&IF(O6="","",IFERROR(INDEX('Raw lists'!$C$2:$C$616,MATCH(O6,'Raw lists'!$C$2:$C$616,0))&" | ",""))&IF(P6="","",IFERROR(INDEX('Raw lists'!$C$2:$C$616,MATCH(P6,'Raw lists'!$C$2:$C$616,0))&" | ","")),LEN(IF(K6="","",IFERROR(INDEX('Raw lists'!$C$2:$C$616,MATCH(K6,'Raw lists'!$C$2:$C$616,0))&" | ",""))&IF(L6="","",IFERROR(INDEX('Raw lists'!$C$2:$C$616,MATCH(L6,'Raw lists'!$C$2:$C$616,0))&" | ",""))&IF(M6="","",IFERROR(INDEX('Raw lists'!$C$2:$C$616,MATCH(M6,'Raw lists'!$C$2:$C$616,0))&" | ",""))&IF(N6="","",IFERROR(INDEX('Raw lists'!$C$2:$C$616,MATCH(N6,'Raw lists'!$C$2:$C$616,0))&" | ",""))&IF(O6="","",IFERROR(INDEX('Raw lists'!$C$2:$C$616,MATCH(O6,'Raw lists'!$C$2:$C$616,0))&" | ",""))&IF(P6="","",IFERROR(INDEX('Raw lists'!$C$2:$C$616,MATCH(P6,'Raw lists'!$C$2:$C$616,0))&" | ","")))-3)) -> Un-polarized Light | Un-polarized | F6: Core | G6: Light vibrating along all possible directions perpendicular to its direction of propagation. | H6: =COUNTIF(C6:E6,"?*") -> 3 | I6: =IF(H6=0,"None",IF(H6=3,"All three",IF(H6=1,"Only "&TRIM(IF(C6<>"","Gemini ","")&IF(D6<>"","RAKE ","")&IF(E6<>"","YAKE","")),SUBSTITUTE(TRIM(IF(C6<>"","Gemini ","")&IF(D6<>"","RAKE ","")&IF(E6<>"","YAKE",""))," "," + ")))) -> All three | K6: Unpolarized Light | L6: Un-polarized Light | M6: Un-polarized | R6: Dark green cells show the phrase each tool extracted for that concept. If a tool matched more than one phrase they are separated by " | ". | T6: Tool | U6: Items returned | V6: Precision | W6: Recall | X6: F1 | Y6: Core-only recall
A7: 6 | B7: Electromagnetic theory of light | C7: =IF(LEN(IF(K7="","",IFERROR(INDEX('Raw lists'!$A$2:$A$192,MATCH(K7,'Raw lists'!$A$2:$A$192,0))&" | ",""))&IF(L7="","",IFERROR(INDEX('Raw lists'!$A$2:$A$192,MATCH(L7,'Raw lists'!$A$2:$A$192,0))&" | ",""))&IF(M7="","",IFERROR(INDEX('Raw lists'!$A$2:$A$192,MATCH(M7,'Raw lists'!$A$2:$A$192,0))&" | ",""))&IF(N7="","",IFERROR(INDEX('Raw lists'!$A$2:$A$192,MATCH(N7,'Raw lists'!$A$2:$A$192,0))&" | ",""))&IF(O7="","",IFERROR(INDEX('Raw lists'!$A$2:$A$192,MATCH(O7,'Raw lists'!$A$2:$A$192,0))&" | ",""))&IF(P7="","",IFERROR(INDEX('Raw lists'!$A$2:$A$192,MATCH(P7,'Raw lists'!$A$2:$A$192,0))&" | ","")))=0,"",LEFT(IF(K7="","",IFERROR(INDEX('Raw lists'!$A$2:$A$192,MATCH(K7,'Raw lists'!$A$2:$A$192,0))&" | ",""))&IF(L7="","",IFERROR(INDEX('Raw lists'!$A$2:$A$192,MATCH(L7,'Raw lists'!$A$2:$A$192,0))&" | ",""))&IF(M7="","",IFERROR(INDEX('Raw lists'!$A$2:$A$192,MATCH(M7,'Raw lists'!$A$2:$A$192,0))&" | ",""))&IF(N7="","",IFERROR(INDEX('Raw lists'!$A$2:$A$192,MATCH(N7,'Raw lists'!$A$2:$A$192,0))&" | ",""))&IF(O7="","",IFERROR(INDEX('Raw lists'!$A$2:$A$192,MATCH(O7,'Raw lists'!$A$2:$A$192,0))&" | ",""))&IF(P7="","",IFERROR(INDEX('Raw lists'!$A$2:$A$192,MATCH(P7,'Raw lists'!$A$2:$A$192,0))&" | ","")),LEN(IF(K7="","",IFERROR(INDEX('Raw lists'!$A$2:$A$192,MATCH(K7,'Raw lists'!$A$2:$A$192,0))&" | ",""))&IF(L7="","",IFERROR(INDEX('Raw lists'!$A$2:$A$192,MATCH(L7,'Raw lists'!$A$2:$A$192,0))&" | ",""))&IF(M7="","",IFERROR(INDEX('Raw lists'!$A$2:$A$192,MATCH(M7,'Raw lists'!$A$2:$A$192,0))&" | ",""))&IF(N7="","",IFERROR(INDEX('Raw lists'!$A$2:$A$192,MATCH(N7,'Raw lists'!$A$2:$A$192,0))&" | ",""))&IF(O7="","",IFERROR(INDEX('Raw lists'!$A$2:$A$192,MATCH(O7,'Raw lists'!$A$2:$A$192,0))&" | ",""))&IF(P7="","",IFERROR(INDEX('Raw lists'!$A$2:$A$192,MATCH(P7,'Raw lists'!$A$2:$A$192,0))&" | ","")))-3)) | D7: =IF(LEN(IF(K7="","",IFERROR(INDEX('Raw lists'!$B$2:$B$627,MATCH(K7,'Raw lists'!$B$2:$B$627,0))&" | ",""))&IF(L7="","",IFERROR(INDEX('Raw lists'!$B$2:$B$627,MATCH(L7,'Raw lists'!$B$2:$B$627,0))&" | ",""))&IF(M7="","",IFERROR(INDEX('Raw lists'!$B$2:$B$627,MATCH(M7,'Raw lists'!$B$2:$B$627,0))&" | ",""))&IF(N7="","",IFERROR(INDEX('Raw lists'!$B$2:$B$627,MATCH(N7,'Raw lists'!$B$2:$B$627,0))&" | ",""))&IF(O7="","",IFERROR(INDEX('Raw lists'!$B$2:$B$627,MATCH(O7,'Raw lists'!$B$2:$B$627,0))&" | ",""))&IF(P7="","",IFERROR(INDEX('Raw lists'!$B$2:$B$627,MATCH(P7,'Raw lists'!$B$2:$B$627,0))&" | ","")))=0,"",LEFT(IF(K7="","",IFERROR(INDEX('Raw lists'!$B$2:$B$627,MATCH(K7,'Raw lists'!$B$2:$B$627,0))&" | ",""))&IF(L7="","",IFERROR(INDEX('Raw lists'!$B$2:$B$627,MATCH(L7,'Raw lists'!$B$2:$B$627,0))&" | ",""))&IF(M7="","",IFERROR(INDEX('Raw lists'!$B$2:$B$627,MATCH(M7,'Raw lists'!$B$2:$B$627,0))&" | ",""))&IF(N7="","",IFERROR(INDEX('Raw lists'!$B$2:$B$627,MATCH(N7,'Raw lists'!$B$2:$B$627,0))&" | ",""))&IF(O7="","",IFERROR(INDEX('Raw lists'!$B$2:$B$627,MATCH(O7,'Raw lists'!$B$2:$B$627,0))&" | ",""))&IF(P7="","",IFERROR(INDEX('Raw lists'!$B$2:$B$627,MATCH(P7,'Raw lists'!$B$2:$B$627,0))&" | ","")),LEN(IF(K7="","",IFERROR(INDEX('Raw lists'!$B$2:$B$627,MATCH(K7,'Raw lists'!$B$2:$B$627,0))&" | ",""))&IF(L7="","",IFERROR(INDEX('Raw lists'!$B$2:$B$627,MATCH(L7,'Raw lists'!$B$2:$B$627,0))&" | ",""))&IF(M7="","",IFERROR(INDEX('Raw lists'!$B$2:$B$627,MATCH(M7,'Raw lists'!$B$2:$B$627,0))&" | ",""))&IF(N7="","",IFERROR(INDEX('Raw lists'!$B$2:$B$627,MATCH(N7,'Raw lists'!$B$2:$B$627,0))&" | ",""))&IF(O7="","",IFERROR(INDEX('Raw lists'!$B$2:$B$627,MATCH(O7,'Raw lists'!$B$2:$B$627,0))&" | ",""))&IF(P7="","",IFERROR(INDEX('Raw lists'!$B$2:$B$627,MATCH(P7,'Raw lists'!$B$2:$B$627,0))&" | ","")))-3)) -> Electromagnetic Theory | E7: =IF(LEN(IF(K7="","",IFERROR(INDEX('Raw lists'!$C$2:$C$616,MATCH(K7,'Raw lists'!$C$2:$C$616,0))&" | ",""))&IF(L7="","",IFERROR(INDEX('Raw lists'!$C$2:$C$616,MATCH(L7,'Raw lists'!$C$2:$C$616,0))&" | ",""))&IF(M7="","",IFERROR(INDEX('Raw lists'!$C$2:$C$616,MATCH(M7,'Raw lists'!$C$2:$C$616,0))&" | ",""))&IF(N7="","",IFERROR(INDEX('Raw lists'!$C$2:$C$616,MATCH(N7,'Raw lists'!$C$2:$C$616,0))&" | ",""))&IF(O7="","",IFERROR(INDEX('Raw lists'!$C$2:$C$616,MATCH(O7,'Raw lists'!$C$2:$C$616,0))&" | ",""))&IF(P7="","",IFERROR(INDEX('Raw lists'!$C$2:$C$616,MATCH(P7,'Raw lists'!$C$2:$C$616,0))&" | ","")))=0,"",LEFT(IF(K7="","",IFERROR(INDEX('Raw lists'!$C$2:$C$616,MATCH(K7,'Raw lists'!$C$2:$C$616,0))&" | ",""))&IF(L7="","",IFERROR(INDEX('Raw lists'!$C$2:$C$616,MATCH(L7,'Raw lists'!$C$2:$C$616,0))&" | ",""))&IF(M7="","",IFERROR(INDEX('Raw lists'!$C$2:$C$616,MATCH(M7,'Raw lists'!$C$2:$C$616,0))&" | ",""))&IF(N7="","",IFERROR(INDEX('Raw lists'!$C$2:$C$616,MATCH(N7,'Raw lists'!$C$2:$C$616,0))&" | ",""))&IF(O7="","",IFERROR(INDEX('Raw lists'!$C$2:$C$616,MATCH(O7,'Raw lists'!$C$2:$C$616,0))&" | ",""))&IF(P7="","",IFERROR(INDEX('Raw lists'!$C$2:$C$616,MATCH(P7,'Raw lists'!$C$2:$C$616,0))&" | ","")),LEN(IF(K7="","",IFERROR(INDEX('Raw lists'!$C$2:$C$616,MATCH(K7,'Raw lists'!$C$2:$C$616,0))&" | ",""))&IF(L7="","",IFERROR(INDEX('Raw lists'!$C$2:$C$616,MATCH(L7,'Raw lists'!$C$2:$C$616,0))&" | ",""))&IF(M7="","",IFERROR(INDEX('Raw lists'!$C$2:$C$616,MATCH(M7,'Raw lists'!$C$2:$C$616,0))&" | ",""))&IF(N7="","",IFERROR(INDEX('Raw lists'!$C$2:$C$616,MATCH(N7,'Raw lists'!$C$2:$C$616,0))&" | ",""))&IF(O7="","",IFERROR(INDEX('Raw lists'!$C$2:$C$616,MATCH(O7,'Raw lists'!$C$2:$C$616,0))&" | ",""))&IF(P7="","",IFERROR(INDEX('Raw lists'!$C$2:$C$616,MATCH(P7,'Raw lists'!$C$2:$C$616,0))&" | ","")))-3)) | F7: Core | G7: Light as electric and magnetic vectors vibrating in a plane transverse to the direction of propagation. | H7: =COUNTIF(C7:E7,"?*") -> 1 | I7: =IF(H7=0,"None",IF(H7=3,"All three",IF(H7=1,"Only "&TRIM(IF(C7<>"","Gemini ","")&IF(D7<>"","RAKE ","")&IF(E7<>"","YAKE","")),SUBSTITUTE(TRIM(IF(C7<>"","Gemini ","")&IF(D7<>"","RAKE ","")&IF(E7<>"","YAKE",""))," "," + ")))) -> Only RAKE | K7: Electromagnetic Theory | T7: Gemini | U7: 191 | V7: 0.42 | W7: 0.41 | X7: 0.42 | Y7: 0.39
A8: 7 | B8: Electric and magnetic vectors | C8: =IF(LEN(IF(K8="","",IFERROR(INDEX('Raw lists'!$A$2:$A$192,MATCH(K8,'Raw lists'!$A$2:$A$192,0))&" | ",""))&IF(L8="","",IFERROR(INDEX('Raw lists'!$A$2:$A$192,MATCH(L8,'Raw lists'!$A$2:$A$192,0))&" | ",""))&IF(M8="","",IFERROR(INDEX('Raw lists'!$A$2:$A$192,MATCH(M8,'Raw lists'!$A$2:$A$192,0))&" | ",""))&IF(N8="","",IFERROR(INDEX('Raw lists'!$A$2:$A$192,MATCH(N8,'Raw lists'!$A$2:$A$192,0))&" | ",""))&IF(O8="","",IFERROR(INDEX('Raw lists'!$A$2:$A$192,MATCH(O8,'Raw lists'!$A$2:$A$192,0))&" | ",""))&IF(P8="","",IFERROR(INDEX('Raw lists'!$A$2:$A$192,MATCH(P8,'Raw lists'!$A$2:$A$192,0))&" | ","")))=0,"",LEFT(IF(K8="","",IFERROR(INDEX('Raw lists'!$A$2:$A$192,MATCH(K8,'Raw lists'!$A$2:$A$192,0))&" | ",""))&IF(L8="","",IFERROR(INDEX('Raw lists'!$A$2:$A$192,MATCH(L8,'Raw lists'!$A$2:$A$192,0))&" | ",""))&IF(M8="","",IFERROR(INDEX('Raw lists'!$A$2:$A$192,MATCH(M8,'Raw lists'!$A$2:$A$192,0))&" | ",""))&IF(N8="","",IFERROR(INDEX('Raw lists'!$A$2:$A$192,MATCH(N8,'Raw lists'!$A$2:$A$192,0))&" | ",""))&IF(O8="","",IFERROR(INDEX('Raw lists'!$A$2:$A$192,MATCH(O8,'Raw lists'!$A$2:$A$192,0))&" | ",""))&IF(P8="","",IFERROR(INDEX('Raw lists'!$A$2:$A$192,MATCH(P8,'Raw lists'!$A$2:$A$192,0))&" | ","")),LEN(IF(K8="","",IFERROR(INDEX('Raw lists'!$A$2:$A$192,MATCH(K8,'Raw lists'!$A$2:$A$192,0))&" | ",""))&IF(L8="","",IFERROR(INDEX('Raw lists'!$A$2:$A$192,MATCH(L8,'Raw lists'!$A$2:$A$192,0))&" | ",""))&IF(M8="","",IFERROR(INDEX('Raw lists'!$A$2:$A$192,MATCH(M8,'Raw lists'!$A$2:$A$192,0))&" | ",""))&IF(N8="","",IFERROR(INDEX('Raw lists'!$A$2:$A$192,MATCH(N8,'Raw lists'!$A$2:$A$192,0))&" | ",""))&IF(O8="","",IFERROR(INDEX('Raw lists'!$A$2:$A$192,MATCH(O8,'Raw lists'!$A$2:$A$192,0))&" | ",""))&IF(P8="","",IFERROR(INDEX('Raw lists'!$A$2:$A$192,MATCH(P8,'Raw lists'!$A$2:$A$192,0))&" | ","")))-3)) | D8: =IF(LEN(IF(K8="","",IFERROR(INDEX('Raw lists'!$B$2:$B$627,MATCH(K8,'Raw lists'!$B$2:$B$627,0))&" | ",""))&IF(L8="","",IFERROR(INDEX('Raw lists'!$B$2:$B$627,MATCH(L8,'Raw lists'!$B$2:$B$627,0))&" | ",""))&IF(M8="","",IFERROR(INDEX('Raw lists'!$B$2:$B$627,MATCH(M8,'Raw lists'!$B$2:$B$627,0))&" | ",""))&IF(N8="","",IFERROR(INDEX('Raw lists'!$B$2:$B$627,MATCH(N8,'Raw lists'!$B$2:$B$627,0))&" | ",""))&IF(O8="","",IFERROR(INDEX('Raw lists'!$B$2:$B$627,MATCH(O8,'Raw lists'!$B$2:$B$627,0))&" | ",""))&IF(P8="","",IFERROR(INDEX('Raw lists'!$B$2:$B$627,MATCH(P8,'Raw lists'!$B$2:$B$627,0))&" | ","")))=0,"",LEFT(IF(K8="","",IFERROR(INDEX('Raw lists'!$B$2:$B$627,MATCH(K8,'Raw lists'!$B$2:$B$627,0))&" | ",""))&IF(L8="","",IFERROR(INDEX('Raw lists'!$B$2:$B$627,MATCH(L8,'Raw lists'!$B$2:$B$627,0))&" | ",""))&IF(M8="","",IFERROR(INDEX('Raw lists'!$B$2:$B$627,MATCH(M8,'Raw lists'!$B$2:$B$627,0))&" | ",""))&IF(N8="","",IFERROR(INDEX('Raw lists'!$B$2:$B$627,MATCH(N8,'Raw lists'!$B$2:$B$627,0))&" | ",""))&IF(O8="","",IFERROR(INDEX('Raw lists'!$B$2:$B$627,MATCH(O8,'Raw lists'!$B$2:$B$627,0))&" | ",""))&IF(P8="","",IFERROR(INDEX('Raw lists'!$B$2:$B$627,MATCH(P8,'Raw lists'!$B$2:$B$627,0))&" | ","")),LEN(IF(K8="","",IFERROR(INDEX('Raw lists'!$B$2:$B$627,MATCH(K8,'Raw lists'!$B$2:$B$627,0))&" | ",""))&IF(L8="","",IFERROR(INDEX('Raw lists'!$B$2:$B$627,MATCH(L8,'Raw lists'!$B$2:$B$627,0))&" | ",""))&IF(M8="","",IFERROR(INDEX('Raw lists'!$B$2:$B$627,MATCH(M8,'Raw lists'!$B$2:$B$627,0))&" | ",""))&IF(N8="","",IFERROR(INDEX('Raw lists'!$B$2:$B$627,MATCH(N8,'Raw lists'!$B$2:$B$627,0))&" | ",""))&IF(O8="","",IFERROR(INDEX('Raw lists'!$B$2:$B$627,MATCH(O8,'Raw lists'!$B$2:$B$627,0))&" | ",""))&IF(P8="","",IFERROR(INDEX('Raw lists'!$B$2:$B$627,MATCH(P8,'Raw lists'!$B$2:$B$627,0))&" | ","")))-3)) -> Electric Vector | Magnetic Vector | Magnetic Field Vectors | E8: =IF(LEN(IF(K8="","",IFERROR(INDEX('Raw lists'!$C$2:$C$616,MATCH(K8,'Raw lists'!$C$2:$C$616,0))&" | ",""))&IF(L8="","",IFERROR(INDEX('Raw lists'!$C$2:$C$616,MATCH(L8,'Raw lists'!$C$2:$C$616,0))&" | ",""))&IF(M8="","",IFERROR(INDEX('Raw lists'!$C$2:$C$616,MATCH(M8,'Raw lists'!$C$2:$C$616,0))&" | ",""))&IF(N8="","",IFERROR(INDEX('Raw lists'!$C$2:$C$616,MATCH(N8,'Raw lists'!$C$2:$C$616,0))&" | ",""))&IF(O8="","",IFERROR(INDEX('Raw lists'!$C$2:$C$616,MATCH(O8,'Raw lists'!$C$2:$C$616,0))&" | ",""))&IF(P8="","",IFERROR(INDEX('Raw lists'!$C$2:$C$616,MATCH(P8,'Raw lists'!$C$2:$C$616,0))&" | ","")))=0,"",LEFT(IF(K8="","",IFERROR(INDEX('Raw lists'!$C$2:$C$616,MATCH(K8,'Raw lists'!$C$2:$C$616,0))&" | ",""))&IF(L8="","",IFERROR(INDEX('Raw lists'!$C$2:$C$616,MATCH(L8,'Raw lists'!$C$2:$C$616,0))&" | ",""))&IF(M8="","",IFERROR(INDEX('Raw lists'!$C$2:$C$616,MATCH(M8,'Raw lists'!$C$2:$C$616,0))&" | ",""))&IF(N8="","",IFERROR(INDEX('Raw lists'!$C$2:$C$616,MATCH(N8,'Raw lists'!$C$2:$C$616,0))&" | ",""))&IF(O8="","",IFERROR(INDEX('Raw lists'!$C$2:$C$616,MATCH(O8,'Raw lists'!$C$2:$C$616,0))&" | ",""))&IF(P8="","",IFERROR(INDEX('Raw lists'!$C$2:$C$616,MATCH(P8,'Raw lists'!$C$2:$C$616,0))&" | ","")),LEN(IF(K8="","",IFERROR(INDEX('Raw lists'!$C$2:$C$616,MATCH(K8,'Raw lists'!$C$2:$C$616,0))&" | ",""))&IF(L8="","",IFERROR(INDEX('Raw lists'!$C$2:$C$616,MATCH(L8,'Raw lists'!$C$2:$C$616,0))&" | ",""))&IF(M8="","",IFERROR(INDEX('Raw lists'!$C$2:$C$616,MATCH(M8,'Raw lists'!$C$2:$C$616,0))&" | ",""))&IF(N8="","",IFERROR(INDEX('Raw lists'!$C$2:$C$616,MATCH(N8,'Raw lists'!$C$2:$C$616,0))&" | ",""))&IF(O8="","",IFERROR(INDEX('Raw lists'!$C$2:$C$616,MATCH(O8,'Raw lists'!$C$2:$C$616,0))&" | ",""))&IF(P8="","",IFERROR(INDEX('Raw lists'!$C$2:$C$616,MATCH(P8,'Raw lists'!$C$2:$C$616,0))&" | ","")))-3)) | F8: Core | G8: The vibrating vectors of light; only the electric vector is drawn when explaining polarization. | H8: =COUNTIF(C8:E8,"?*") -> 1 | I8: =IF(H8=0,"None",IF(H8=3,"All three",IF(H8=1,"Only "&TRIM(IF(C8<>"","Gemini ","")&IF(D8<>"","RAKE ","")&IF(E8<>"","YAKE","")),SUBSTITUTE(TRIM(IF(C8<>"","Gemini ","")&IF(D8<>"","RAKE ","")&IF(E8<>"","YAKE",""))," "," + ")))) -> Only RAKE | K8: Electric Vector | L8: Magnetic Vector | M8: Magnetic Field Vectors | R8: Rows 2 to 139 are Claude's concepts. The grey rows below them list every other item from the three text files. Columns K to P (grey headers) hold the tool phrases that count as a match; edit them and the green cells update. | T8: YAKE | U8: 615 | V8: 0.27 | W8: 0.71 | X8: 0.39 | Y8: 0.74
A9: 8 | B9: Tourmaline crystal | C9: =IF(LEN(IF(K9="","",IFERROR(INDEX('Raw lists'!$A$2:$A$192,MATCH(K9,'Raw lists'!$A$2:$A$192,0))&" | ",""))&IF(L9="","",IFERROR(INDEX('Raw lists'!$A$2:$A$192,MATCH(L9,'Raw lists'!$A$2:$A$192,0))&" | ",""))&IF(M9="","",IFERROR(INDEX('Raw lists'!$A$2:$A$192,MATCH(M9,'Raw lists'!$A$2:$A$192,0))&" | ",""))&IF(N9="","",IFERROR(INDEX('Raw lists'!$A$2:$A$192,MATCH(N9,'Raw lists'!$A$2:$A$192,0))&" | ",""))&IF(O9="","",IFERROR(INDEX('Raw lists'!$A$2:$A$192,MATCH(O9,'Raw lists'!$A$2:$A$192,0))&" | ",""))&IF(P9="","",IFERROR(INDEX('Raw lists'!$A$2:$A$192,MATCH(P9,'Raw lists'!$A$2:$A$192,0))&" | ","")))=0,"",LEFT(IF(K9="","",IFERROR(INDEX('Raw lists'!$A$2:$A$192,MATCH(K9,'Raw lists'!$A$2:$A$192,0))&" | ",""))&IF(L9="","",IFERROR(INDEX('Raw lists'!$A$2:$A$192,MATCH(L9,'Raw lists'!$A$2:$A$192,0))&" | ",""))&IF(M9="","",IFERROR(INDEX('Raw lists'!$A$2:$A$192,MATCH(M9,'Raw lists'!$A$2:$A$192,0))&" | ",""))&IF(N9="","",IFERROR(INDEX('Raw lists'!$A$2:$A$192,MATCH(N9,'Raw lists'!$A$2:$A$192,0))&" | ",""))&IF(O9="","",IFERROR(INDEX('Raw lists'!$A$2:$A$192,MATCH(O9,'Raw lists'!$A$2:$A$192,0))&" | ",""))&IF(P9="","",IFERROR(INDEX('Raw lists'!$A$2:$A$192,MATCH(P9,'Raw lists'!$A$2:$A$192,0))&" | ","")),LEN(IF(K9="","",IFERROR(INDEX('Raw lists'!$A$2:$A$192,MATCH(K9,'Raw lists'!$A$2:$A$192,0))&" | ",""))&IF(L9="","",IFERROR(INDEX('Raw lists'!$A$2:$A$192,MATCH(L9,'Raw lists'!$A$2:$A$192,0))&" | ",""))&IF(M9="","",IFERROR(INDEX('Raw lists'!$A$2:$A$192,MATCH(M9,'Raw lists'!$A$2:$A$192,0))&" | ",""))&IF(N9="","",IFERROR(INDEX('Raw lists'!$A$2:$A$192,MATCH(N9,'Raw lists'!$A$2:$A$192,0))&" | ",""))&IF(O9="","",IFERROR(INDEX('Raw lists'!$A$2:$A$192,MATCH(O9,'Raw lists'!$A$2:$A$192,0))&" | ",""))&IF(P9="","",IFERROR(INDEX('Raw lists'!$A$2:$A$192,MATCH(P9,'Raw lists'!$A$2:$A$192,0))&" | ","")))-3)) | D9: =IF(LEN(IF(K9="","",IFERROR(INDEX('Raw lists'!$B$2:$B$627,MATCH(K9,'Raw lists'!$B$2:$B$627,0))&" | ",""))&IF(L9="","",IFERROR(INDEX('Raw lists'!$B$2:$B$627,MATCH(L9,'Raw lists'!$B$2:$B$627,0))&" | ",""))&IF(M9="","",IFERROR(INDEX('Raw lists'!$B$2:$B$627,MATCH(M9,'Raw lists'!$B$2:$B$627,0))&" | ",""))&IF(N9="","",IFERROR(INDEX('Raw lists'!$B$2:$B$627,MATCH(N9,'Raw lists'!$B$2:$B$627,0))&" | ",""))&IF(O9="","",IFERROR(INDEX('Raw lists'!$B$2:$B$627,MATCH(O9,'Raw lists'!$B$2:$B$627,0))&" | ",""))&IF(P9="","",IFERROR(INDEX('Raw lists'!$B$2:$B$627,MATCH(P9,'Raw lists'!$B$2:$B$627,0))&" | ","")))=0,"",LEFT(IF(K9="","",IFERROR(INDEX('Raw lists'!$B$2:$B$627,MATCH(K9,'Raw lists'!$B$2:$B$627,0))&" | ",""))&IF(L9="","",IFERROR(INDEX('Raw lists'!$B$2:$B$627,MATCH(L9,'Raw lists'!$B$2:$B$627,0))&" | ",""))&IF(M9="","",IFERROR(INDEX('Raw lists'!$B$2:$B$627,MATCH(M9,'Raw lists'!$B$2:$B$627,0))&" | ",""))&IF(N9="","",IFERROR(INDEX('Raw lists'!$B$2:$B$627,MATCH(N9,'Raw lists'!$B$2:$B$627,0))&" | ",""))&IF(O9="","",IFERROR(INDEX('Raw lists'!$B$2:$B$627,MATCH(O9,'Raw lists'!$B$2:$B$627,0))&" | ",""))&IF(P9="","",IFERROR(INDEX('Raw lists'!$B$2:$B$627,MATCH(P9,'Raw lists'!$B$2:$B$627,0))&" | ","")),LEN(IF(K9="","",IFERROR(INDEX('Raw lists'!$B$2:$B$627,MATCH(K9,'Raw lists'!$B$2:$B$627,0))&" | ",""))&IF(L9="","",IFERROR(INDEX('Raw lists'!$B$2:$B$627,MATCH(L9,'Raw lists'!$B$2:$B$627,0))&" | ",""))&IF(M9="","",IFERROR(INDEX('Raw lists'!$B$2:$B$627,MATCH(M9,'Raw lists'!$B$2:$B$627,0))&" | ",""))&IF(N9="","",IFERROR(INDEX('Raw lists'!$B$2:$B$627,MATCH(N9,'Raw lists'!$B$2:$B$627,0))&" | ",""))&IF(O9="","",IFERROR(INDEX('Raw lists'!$B$2:$B$627,MATCH(O9,'Raw lists'!$B$2:$B$627,0))&" | ",""))&IF(P9="","",IFERROR(INDEX('Raw lists'!$B$2:$B$627,MATCH(P9,'Raw lists'!$B$2:$B$627,0))&" | ","")))-3)) -> Tourmaline | Single Tourmaline Crystal | E9: =IF(LEN(IF(K9="","",IFERROR(INDEX('Raw lists'!$C$2:$C$616,MATCH(K9,'Raw lists'!$C$2:$C$616,0))&" | ",""))&IF(L9="","",IFERROR(INDEX('Raw lists'!$C$2:$C$616,MATCH(L9,'Raw lists'!$C$2:$C$616,0))&" | ",""))&IF(M9="","",IFERROR(INDEX('Raw lists'!$C$2:$C$616,MATCH(M9,'Raw lists'!$C$2:$C$616,0))&" | ",""))&IF(N9="","",IFERROR(INDEX('Raw lists'!$C$2:$C$616,MATCH(N9,'Raw lists'!$C$2:$C$616,0))&" | ",""))&IF(O9="","",IFERROR(INDEX('Raw lists'!$C$2:$C$616,MATCH(O9,'Raw lists'!$C$2:$C$616,0))&" | ",""))&IF(P9="","",IFERROR(INDEX('Raw lists'!$C$2:$C$616,MATCH(P9,'Raw lists'!$C$2:$C$616,0))&" | ","")))=0,"",LEFT(IF(K9="","",IFERROR(INDEX('Raw lists'!$C$2:$C$616,MATCH(K9,'Raw lists'!$C$2:$C$616,0))&" | ",""))&IF(L9="","",IFERROR(INDEX('Raw lists'!$C$2:$C$616,MATCH(L9,'Raw lists'!$C$2:$C$616,0))&" | ",""))&IF(M9="","",IFERROR(INDEX('Raw lists'!$C$2:$C$616,MATCH(M9,'Raw lists'!$C$2:$C$616,0))&" | ",""))&IF(N9="","",IFERROR(INDEX('Raw lists'!$C$2:$C$616,MATCH(N9,'Raw lists'!$C$2:$C$616,0))&" | ",""))&IF(O9="","",IFERROR(INDEX('Raw lists'!$C$2:$C$616,MATCH(O9,'Raw lists'!$C$2:$C$616,0))&" | ",""))&IF(P9="","",IFERROR(INDEX('Raw lists'!$C$2:$C$616,MATCH(P9,'Raw lists'!$C$2:$C$616,0))&" | ","")),LEN(IF(K9="","",IFERROR(INDEX('Raw lists'!$C$2:$C$616,MATCH(K9,'Raw lists'!$C$2:$C$616,0))&" | ",""))&IF(L9="","",IFERROR(INDEX('Raw lists'!$C$2:$C$616,MATCH(L9,'Raw lists'!$C$2:$C$616,0))&" | ",""))&IF(M9="","",IFERROR(INDEX('Raw lists'!$C$2:$C$616,MATCH(M9,'Raw lists'!$C$2:$C$616,0))&" | ",""))&IF(N9="","",IFERROR(INDEX('Raw lists'!$C$2:$C$616,MATCH(N9,'Raw lists'!$C$2:$C$616,0))&" | ",""))&IF(O9="","",IFERROR(INDEX('Raw lists'!$C$2:$C$616,MATCH(O9,'Raw lists'!$C$2:$C$616,0))&" | ",""))&IF(P9="","",IFERROR(INDEX('Raw lists'!$C$2:$C$616,MATCH(P9,'Raw lists'!$C$2:$C$616,0))&" | ","")))-3)) | F9: Example | G9: Crystal used to show that rotating it changes the intensity of polarized light but not of unpolarized light. | H9: =COUNTIF(C9:E9,"?*") -> 1 | I9: =IF(H9=0,"None",IF(H9=3,"All three",IF(H9=1,"Only "&TRIM(IF(C9<>"","Gemini ","")&IF(D9<>"","RAKE ","")&IF(E9<>"","YAKE","")),SUBSTITUTE(TRIM(IF(C9<>"","Gemini ","")&IF(D9<>"","RAKE ","")&IF(E9<>"","YAKE",""))," "," + ")))) -> Only RAKE | K9: Tourmaline | L9: Single Tourmaline Crystal | T9: RAKE | U9: 626 | V9: 0.24 | W9: 0.7 | X9: 0.36 | Y9: 0.7
A10: 9 | B10: Principal section | C10: =IF(LEN(IF(K10="","",IFERROR(INDEX('Raw lists'!$A$2:$A$192,MATCH(K10,'Raw lists'!$A$2:$A$192,0))&" | ",""))&IF(L10="","",IFERROR(INDEX('Raw lists'!$A$2:$A$192,MATCH(L10,'Raw lists'!$A$2:$A$192,0))&" | ",""))&IF(M10="","",IFERROR(INDEX('Raw lists'!$A$2:$A$192,MATCH(M10,'Raw lists'!$A$2:$A$192,0))&" | ",""))&IF(N10="","",IFERROR(INDEX('Raw lists'!$A$2:$A$192,MATCH(N10,'Raw lists'!$A$2:$A$192,0))&" | ",""))&IF(O10="","",IFERROR(INDEX('Raw lists'!$A$2:$A$192,MATCH(O10,'Raw lists'!$A$2:$A$192,0))&" | ",""))&IF(P10="","",IFERROR(INDEX('Raw lists'!$A$2:$A$192,MATCH(P10,'Raw lists'!$A$2:$A$192,0))&" | ","")))=0,"",LEFT(IF(K10="","",IFERROR(INDEX('Raw lists'!$A$2:$A$192,MATCH(K10,'Raw lists'!$A$2:$A$192,0))&" | ",""))&IF(L10="","",IFERROR(INDEX('Raw lists'!$A$2:$A$192,MATCH(L10,'Raw lists'!$A$2:$A$192,0))&" | ",""))&IF(M10="","",IFERROR(INDEX('Raw lists'!$A$2:$A$192,MATCH(M10,'Raw lists'!$A$2:$A$192,0))&" | ",""))&IF(N10="","",IFERROR(INDEX('Raw lists'!$A$2:$A$192,MATCH(N10,'Raw lists'!$A$2:$A$192,0))&" | ",""))&IF(O10="","",IFERROR(INDEX('Raw lists'!$A$2:$A$192,MATCH(O10,'Raw lists'!$A$2:$A$192,0))&" | ",""))&IF(P10="","",IFERROR(INDEX('Raw lists'!$A$2:$A$192,MATCH(P10,'Raw lists'!$A$2:$A$192,0))&" | ","")),LEN(IF(K10="","",IFERROR(INDEX('Raw lists'!$A$2:$A$192,MATCH(K10,'Raw lists'!$A$2:$A$192,0))&" | ",""))&IF(L10="","",IFERROR(INDEX('Raw lists'!$A$2:$A$192,MATCH(L10,'Raw lists'!$A$2:$A$192,0))&" | ",""))&IF(M10="","",IFERROR(INDEX('Raw lists'!$A$2:$A$192,MATCH(M10,'Raw lists'!$A$2:$A$192,0))&" | ",""))&IF(N10="","",IFERROR(INDEX('Raw lists'!$A$2:$A$192,MATCH(N10,'Raw lists'!$A$2:$A$192,0))&" | ",""))&IF(O10="","",IFERROR(INDEX('Raw lists'!$A$2:$A$192,MATCH(O10,'Raw lists'!$A$2:$A$192,0))&" | ",""))&IF(P10="","",IFERROR(INDEX('Raw lists'!$A$2:$A$192,MATCH(P10,'Raw lists'!$A$2:$A$192,0))&" | ","")))-3)) -> Principal Section | D10: =IF(LEN(IF(K10="","",IFERROR(INDEX('Raw lists'!$B$2:$B$627,MATCH(K10,'Raw lists'!$B$2:$B$627,0))&" | ",""))&IF(L10="","",IFERROR(INDEX('Raw lists'!$B$2:$B$627,MATCH(L10,'Raw lists'!$B$2:$B$627,0))&" | ",""))&IF(M10="","",IFERROR(INDEX('Raw lists'!$B$2:$B$627,MATCH(M10,'Raw lists'!$B$2:$B$627,0))&" | ",""))&IF(N10="","",IFERROR(INDEX('Raw lists'!$B$2:$B$627,MATCH(N10,'Raw lists'!$B$2:$B$627,0))&" | ",""))&IF(O10="","",IFERROR(INDEX('Raw lists'!$B$2:$B$627,MATCH(O10,'Raw lists'!$B$2:$B$627,0))&" | ",""))&IF(P10="","",IFERROR(INDEX('Raw lists'!$B$2:$B$627,MATCH(P10,'Raw lists'!$B$2:$B$627,0))&" | ","")))=0,"",LEFT(IF(K10="","",IFERROR(INDEX('Raw lists'!$B$2:$B$627,MATCH(K10,'Raw lists'!$B$2:$B$627,0))&" | ",""))&IF(L10="","",IFERROR(INDEX('Raw lists'!$B$2:$B$627,MATCH(L10,'Raw lists'!$B$2:$B$627,0))&" | ",""))&IF(M10="","",IFERROR(INDEX('Raw lists'!$B$2:$B$627,MATCH(M10,'Raw lists'!$B$2:$B$627,0))&" | ",""))&IF(N10="","",IFERROR(INDEX('Raw lists'!$B$2:$B$627,MATCH(N10,'Raw lists'!$B$2:$B$627,0))&" | ",""))&IF(O10="","",IFERROR(INDEX('Raw lists'!$B$2:$B$627,MATCH(O10,'Raw lists'!$B$2:$B$627,0))&" | ",""))&IF(P10="","",IFERROR(INDEX('Raw lists'!$B$2:$B$627,MATCH(P10,'Raw lists'!$B$2:$B$627,0))&" | ","")),LEN(IF(K10="","",IFERROR(INDEX('Raw lists'!$B$2:$B$627,MATCH(K10,'Raw lists'!$B$2:$B$627,0))&" | ",""))&IF(L10="","",IFERROR(INDEX('Raw lists'!$B$2:$B$627,MATCH(L10,'Raw lists'!$B$2:$B$627,0))&" | ",""))&IF(M10="","",IFERROR(INDEX('Raw lists'!$B$2:$B$627,MATCH(M10,'Raw lists'!$B$2:$B$627,0))&" | ",""))&IF(N10="","",IFERROR(INDEX('Raw lists'!$B$2:$B$627,MATCH(N10,'Raw lists'!$B$2:$B$627,0))&" | ",""))&IF(O10="","",IFERROR(INDEX('Raw lists'!$B$2:$B$627,MATCH(O10,'Raw lists'!$B$2:$B$627,0))&" | ",""))&IF(P10="","",IFERROR(INDEX('Raw lists'!$B$2:$B$627,MATCH(P10,'Raw lists'!$B$2:$B$627,0))&" | ","")))-3)) -> Principal Section | E10: =IF(LEN(IF(K10="","",IFERROR(INDEX('Raw lists'!$C$2:$C$616,MATCH(K10,'Raw lists'!$C$2:$C$616,0))&" | ",""))&IF(L10="","",IFERROR(INDEX('Raw lists'!$C$2:$C$616,MATCH(L10,'Raw lists'!$C$2:$C$616,0))&" | ",""))&IF(M10="","",IFERROR(INDEX('Raw lists'!$C$2:$C$616,MATCH(M10,'Raw lists'!$C$2:$C$616,0))&" | ",""))&IF(N10="","",IFERROR(INDEX('Raw lists'!$C$2:$C$616,MATCH(N10,'Raw lists'!$C$2:$C$616,0))&" | ",""))&IF(O10="","",IFERROR(INDEX('Raw lists'!$C$2:$C$616,MATCH(O10,'Raw lists'!$C$2:$C$616,0))&" | ",""))&IF(P10="","",IFERROR(INDEX('Raw lists'!$C$2:$C$616,MATCH(P10,'Raw lists'!$C$2:$C$616,0))&" | ","")))=0,"",LEFT(IF(K10="","",IFERROR(INDEX('Raw lists'!$C$2:$C$616,MATCH(K10,'Raw lists'!$C$2:$C$616,0))&" | ",""))&IF(L10="","",IFERROR(INDEX('Raw lists'!$C$2:$C$616,MATCH(L10,'Raw lists'!$C$2:$C$616,0))&" | ",""))&IF(M10="","",IFERROR(INDEX('Raw lists'!$C$2:$C$616,MATCH(M10,'Raw lists'!$C$2:$C$616,0))&" | ",""))&IF(N10="","",IFERROR(INDEX('Raw lists'!$C$2:$C$616,MATCH(N10,'Raw lists'!$C$2:$C$616,0))&" | ",""))&IF(O10="","",IFERROR(INDEX('Raw lists'!$C$2:$C$616,MATCH(O10,'Raw lists'!$C$2:$C$616,0))&" | ",""))&IF(P10="","",IFERROR(INDEX('Raw lists'!$C$2:$C$616,MATCH(P10,'Raw lists'!$C$2:$C$616,0))&" | ","")),LEN(IF(K10="","",IFERROR(INDEX('Raw lists'!$C$2:$C$616,MATCH(K10,'Raw lists'!$C$2:$C$616,0))&" | ",""))&IF(L10="","",IFERROR(INDEX('Raw lists'!$C$2:$C$616,MATCH(L10,'Raw lists'!$C$2:$C$616,0))&" | ",""))&IF(M10="","",IFERROR(INDEX('Raw lists'!$C$2:$C$616,MATCH(M10,'Raw lists'!$C$2:$C$616,0))&" | ",""))&IF(N10="","",IFERROR(INDEX('Raw lists'!$C$2:$C$616,MATCH(N10,'Raw lists'!$C$2:$C$616,0))&" | ",""))&IF(O10="","",IFERROR(INDEX('Raw lists'!$C$2:$C$616,MATCH(O10,'Raw lists'!$C$2:$C$616,0))&" | ",""))&IF(P10="","",IFERROR(INDEX('Raw lists'!$C$2:$C$616,MATCH(P10,'Raw lists'!$C$2:$C$616,0))&" | ","")))-3)) -> Principal Section | F10: Core | G10: Plane containing the optic axis and perpendicular to the opposite faces of the crystal. | H10: =COUNTIF(C10:E10,"?*") -> 3 | I10: =IF(H10=0,"None",IF(H10=3,"All three",IF(H10=1,"Only "&TRIM(IF(C10<>"","Gemini ","")&IF(D10<>"","RAKE ","")&IF(E10<>"","YAKE","")),SUBSTITUTE(TRIM(IF(C10<>"","Gemini ","")&IF(D10<>"","RAKE ","")&IF(E10<>"","YAKE",""))," "," + ")))) -> All three | K10: Principal Section
